2017-04-27 18:39:14,852 [Thread-2:48780] [django.request:152] [base:get_response] [WARNING]- Not Found: /
2017-04-27 18:39:51,631 [Thread-4:53948] [django.request:152] [base:get_response] [WARNING]- Not Found: /templates/login.html
2017-04-27 18:43:58,801 [Thread-3:49964] [django.request:152] [base:get_response] [WARNING]- Not Found: /web_hook/static/h-ui/css/H-ui.min.css
2017-04-27 18:43:58,835 [Thread-4:43728] [django.request:152] [base:get_response] [WARNING]- Not Found: /web_hook/static/h-ui.admin/css/H-ui.login.css
2017-04-27 18:43:58,838 [Thread-5:52884] [django.request:152] [base:get_response] [WARNING]- Not Found: /web_hook/static/h-ui.admin/css/style.css
2017-04-27 18:43:58,838 [Thread-6:52184] [django.request:152] [base:get_response] [WARNING]- Not Found: /web_hook/lib/Hui-iconfont/1.0.8/iconfont.css
2017-04-27 18:43:58,842 [Thread-7:32256] [django.request:152] [base:get_response] [WARNING]- Not Found: /web_hook/lib/jquery/1.9.1/jquery.min.js
2017-04-27 18:43:58,844 [Thread-8:49840] [django.request:152] [base:get_response] [WARNING]- Not Found: /web_hook/static/h-ui/js/H-ui.min.js
2017-04-27 18:57:38,990 [Thread-2:43280] [django.request:124] [exception:handle_uncaught_exception] [ERROR]- Internal Server Error: /web_hook/check_code
Traceback (most recent call last):
  File "D:\python\2.7\setuppath\lib\site-packages\django\core\handlers\exception.py", line 39, in inner
    response = get_response(request)
  File "D:\python\2.7\setuppath\lib\site-packages\django\core\handlers\base.py", line 187, in _get_response
    response = self.process_exception_by_middleware(e, request)
  File "D:\python\2.7\setuppath\lib\site-packages\django\core\handlers\base.py", line 185, in _get_response
    response = wrapped_callback(request, *callback_args, **callback_kwargs)
  File "E:\my\projects\python\git_web_hooks\apps\views.py", line 40, in check_code
    my_captcha.display()
  File "E:\my\projects\python\git_web_hooks\apps\ext\Captcha.py", line 132, in display
    self.font = ImageFont.truetype(self.font_path.replace('\\', '/'), self.font_size + int(ceil(m)))
  File "D:\python\2.7\setuppath\lib\site-packages\PIL\ImageFont.py", line 227, in truetype
    return FreeTypeFont(filename, size, index, encoding)
  File "D:\python\2.7\setuppath\lib\site-packages\PIL\ImageFont.py", line 134, in __init__
    self.font = core.getfont(file, size, index, encoding)
IOError: cannot open resource
2017-04-27 18:58:15,607 [Thread-8:53780] [django.request:124] [exception:handle_uncaught_exception] [ERROR]- Internal Server Error: /web_hook/check_code
Traceback (most recent call last):
  File "D:\python\2.7\setuppath\lib\site-packages\django\core\handlers\exception.py", line 39, in inner
    response = get_response(request)
  File "D:\python\2.7\setuppath\lib\site-packages\django\core\handlers\base.py", line 187, in _get_response
    response = self.process_exception_by_middleware(e, request)
  File "D:\python\2.7\setuppath\lib\site-packages\django\core\handlers\base.py", line 185, in _get_response
    response = wrapped_callback(request, *callback_args, **callback_kwargs)
  File "E:\my\projects\python\git_web_hooks\apps\views.py", line 40, in check_code
    my_captcha.display()
  File "E:\my\projects\python\git_web_hooks\apps\ext\Captcha.py", line 132, in display
    self.font = ImageFont.truetype(self.font_path.replace('\\', '/'), self.font_size + int(ceil(m)))
  File "D:\python\2.7\setuppath\lib\site-packages\PIL\ImageFont.py", line 227, in truetype
    return FreeTypeFont(filename, size, index, encoding)
  File "D:\python\2.7\setuppath\lib\site-packages\PIL\ImageFont.py", line 134, in __init__
    self.font = core.getfont(file, size, index, encoding)
IOError: cannot open resource
2017-04-28 10:59:47,463 [Thread-7:53112] [django.request:124] [exception:handle_uncaught_exception] [ERROR]- Internal Server Error: /web_hook/check_code
Traceback (most recent call last):
  File "D:\python\2.7\setuppath\lib\site-packages\django\core\handlers\exception.py", line 39, in inner
    response = get_response(request)
  File "D:\python\2.7\setuppath\lib\site-packages\django\utils\deprecation.py", line 138, in __call__
    response = self.process_response(request, response)
  File "D:\python\2.7\setuppath\lib\site-packages\django\contrib\sessions\middleware.py", line 58, in process_response
    request.session.save()
  File "D:\python\2.7\setuppath\lib\site-packages\django\contrib\sessions\backends\db.py", line 81, in save
    return self.create()
  File "D:\python\2.7\setuppath\lib\site-packages\django\contrib\sessions\backends\db.py", line 50, in create
    self._session_key = self._get_new_session_key()
  File "D:\python\2.7\setuppath\lib\site-packages\django\contrib\sessions\backends\base.py", line 164, in _get_new_session_key
    if not self.exists(session_key):
  File "D:\python\2.7\setuppath\lib\site-packages\django\contrib\sessions\backends\db.py", line 46, in exists
    return self.model.objects.filter(session_key=session_key).exists()
  File "D:\python\2.7\setuppath\lib\site-packages\django\db\models\query.py", line 660, in exists
    return self.query.has_results(using=self.db)
  File "D:\python\2.7\setuppath\lib\site-packages\django\db\models\sql\query.py", line 494, in has_results
    return compiler.has_results()
  File "D:\python\2.7\setuppath\lib\site-packages\django\db\models\sql\compiler.py", line 806, in has_results
    return bool(self.execute_sql(SINGLE))
  File "D:\python\2.7\setuppath\lib\site-packages\django\db\models\sql\compiler.py", line 835, in execute_sql
    cursor.execute(sql, params)
  File "D:\python\2.7\setuppath\lib\site-packages\django\db\backends\utils.py", line 79, in execute
    return super(CursorDebugWrapper, self).execute(sql, params)
  File "D:\python\2.7\setuppath\lib\site-packages\django\db\backends\utils.py", line 64, in execute
    return self.cursor.execute(sql, params)
  File "D:\python\2.7\setuppath\lib\site-packages\django\db\utils.py", line 94, in __exit__
    six.reraise(dj_exc_type, dj_exc_value, traceback)
  File "D:\python\2.7\setuppath\lib\site-packages\django\db\backends\utils.py", line 64, in execute
    return self.cursor.execute(sql, params)
  File "D:\python\2.7\setuppath\lib\site-packages\django\db\backends\sqlite3\base.py", line 337, in execute
    return Database.Cursor.execute(self, query, params)
OperationalError: no such table: django_session
2017-04-28 11:12:32,836 [Thread-7:53112] [django.request:124] [exception:handle_uncaught_exception] [ERROR]- Internal Server Error: /web_hook/check_code
Traceback (most recent call last):
  File "D:\python\2.7\setuppath\lib\site-packages\django\core\handlers\exception.py", line 39, in inner
    response = get_response(request)
  File "D:\python\2.7\setuppath\lib\site-packages\django\utils\deprecation.py", line 138, in __call__
    response = self.process_response(request, response)
  File "D:\python\2.7\setuppath\lib\site-packages\django\contrib\sessions\middleware.py", line 58, in process_response
    request.session.save()
  File "D:\python\2.7\setuppath\lib\site-packages\django\contrib\sessions\backends\db.py", line 81, in save
    return self.create()
  File "D:\python\2.7\setuppath\lib\site-packages\django\contrib\sessions\backends\db.py", line 50, in create
    self._session_key = self._get_new_session_key()
  File "D:\python\2.7\setuppath\lib\site-packages\django\contrib\sessions\backends\base.py", line 164, in _get_new_session_key
    if not self.exists(session_key):
  File "D:\python\2.7\setuppath\lib\site-packages\django\contrib\sessions\backends\db.py", line 46, in exists
    return self.model.objects.filter(session_key=session_key).exists()
  File "D:\python\2.7\setuppath\lib\site-packages\django\db\models\query.py", line 660, in exists
    return self.query.has_results(using=self.db)
  File "D:\python\2.7\setuppath\lib\site-packages\django\db\models\sql\query.py", line 494, in has_results
    return compiler.has_results()
  File "D:\python\2.7\setuppath\lib\site-packages\django\db\models\sql\compiler.py", line 806, in has_results
    return bool(self.execute_sql(SINGLE))
  File "D:\python\2.7\setuppath\lib\site-packages\django\db\models\sql\compiler.py", line 835, in execute_sql
    cursor.execute(sql, params)
  File "D:\python\2.7\setuppath\lib\site-packages\django\db\backends\utils.py", line 79, in execute
    return super(CursorDebugWrapper, self).execute(sql, params)
  File "D:\python\2.7\setuppath\lib\site-packages\django\db\backends\utils.py", line 64, in execute
    return self.cursor.execute(sql, params)
  File "D:\python\2.7\setuppath\lib\site-packages\django\db\utils.py", line 94, in __exit__
    six.reraise(dj_exc_type, dj_exc_value, traceback)
  File "D:\python\2.7\setuppath\lib\site-packages\django\db\backends\utils.py", line 64, in execute
    return self.cursor.execute(sql, params)
  File "D:\python\2.7\setuppath\lib\site-packages\django\db\backends\sqlite3\base.py", line 337, in execute
    return Database.Cursor.execute(self, query, params)
OperationalError: no such table: django_session
2017-04-28 11:13:56,994 [Thread-7:40088] [django.request:124] [exception:handle_uncaught_exception] [ERROR]- Internal Server Error: /web_hook/check_code
Traceback (most recent call last):
  File "D:\python\2.7\setuppath\lib\site-packages\django\core\handlers\exception.py", line 39, in inner
    response = get_response(request)
  File "D:\python\2.7\setuppath\lib\site-packages\django\utils\deprecation.py", line 138, in __call__
    response = self.process_response(request, response)
  File "D:\python\2.7\setuppath\lib\site-packages\django\contrib\sessions\middleware.py", line 58, in process_response
    request.session.save()
  File "D:\python\2.7\setuppath\lib\site-packages\django\contrib\sessions\backends\db.py", line 81, in save
    return self.create()
  File "D:\python\2.7\setuppath\lib\site-packages\django\contrib\sessions\backends\db.py", line 50, in create
    self._session_key = self._get_new_session_key()
  File "D:\python\2.7\setuppath\lib\site-packages\django\contrib\sessions\backends\base.py", line 164, in _get_new_session_key
    if not self.exists(session_key):
  File "D:\python\2.7\setuppath\lib\site-packages\django\contrib\sessions\backends\db.py", line 46, in exists
    return self.model.objects.filter(session_key=session_key).exists()
  File "D:\python\2.7\setuppath\lib\site-packages\django\db\models\query.py", line 660, in exists
    return self.query.has_results(using=self.db)
  File "D:\python\2.7\setuppath\lib\site-packages\django\db\models\sql\query.py", line 494, in has_results
    return compiler.has_results()
  File "D:\python\2.7\setuppath\lib\site-packages\django\db\models\sql\compiler.py", line 806, in has_results
    return bool(self.execute_sql(SINGLE))
  File "D:\python\2.7\setuppath\lib\site-packages\django\db\models\sql\compiler.py", line 835, in execute_sql
    cursor.execute(sql, params)
  File "D:\python\2.7\setuppath\lib\site-packages\django\db\backends\utils.py", line 79, in execute
    return super(CursorDebugWrapper, self).execute(sql, params)
  File "D:\python\2.7\setuppath\lib\site-packages\django\db\backends\utils.py", line 64, in execute
    return self.cursor.execute(sql, params)
  File "D:\python\2.7\setuppath\lib\site-packages\django\db\utils.py", line 94, in __exit__
    six.reraise(dj_exc_type, dj_exc_value, traceback)
  File "D:\python\2.7\setuppath\lib\site-packages\django\db\backends\utils.py", line 64, in execute
    return self.cursor.execute(sql, params)
  File "D:\python\2.7\setuppath\lib\site-packages\django\db\backends\sqlite3\base.py", line 337, in execute
    return Database.Cursor.execute(self, query, params)
OperationalError: no such table: django_session
2017-04-28 11:21:42,328 [Thread-7:54800] [django.request:124] [exception:handle_uncaught_exception] [ERROR]- Internal Server Error: /web_hook/check_code
Traceback (most recent call last):
  File "D:\python\2.7\setuppath\lib\site-packages\django\core\handlers\exception.py", line 39, in inner
    response = get_response(request)
  File "D:\python\2.7\setuppath\lib\site-packages\django\utils\deprecation.py", line 138, in __call__
    response = self.process_response(request, response)
  File "D:\python\2.7\setuppath\lib\site-packages\django\contrib\sessions\middleware.py", line 58, in process_response
    request.session.save()
  File "D:\python\2.7\setuppath\lib\site-packages\django\contrib\sessions\backends\db.py", line 81, in save
    return self.create()
  File "D:\python\2.7\setuppath\lib\site-packages\django\contrib\sessions\backends\db.py", line 50, in create
    self._session_key = self._get_new_session_key()
  File "D:\python\2.7\setuppath\lib\site-packages\django\contrib\sessions\backends\base.py", line 164, in _get_new_session_key
    if not self.exists(session_key):
  File "D:\python\2.7\setuppath\lib\site-packages\django\contrib\sessions\backends\db.py", line 46, in exists
    return self.model.objects.filter(session_key=session_key).exists()
  File "D:\python\2.7\setuppath\lib\site-packages\django\db\models\query.py", line 660, in exists
    return self.query.has_results(using=self.db)
  File "D:\python\2.7\setuppath\lib\site-packages\django\db\models\sql\query.py", line 494, in has_results
    return compiler.has_results()
  File "D:\python\2.7\setuppath\lib\site-packages\django\db\models\sql\compiler.py", line 806, in has_results
    return bool(self.execute_sql(SINGLE))
  File "D:\python\2.7\setuppath\lib\site-packages\django\db\models\sql\compiler.py", line 835, in execute_sql
    cursor.execute(sql, params)
  File "D:\python\2.7\setuppath\lib\site-packages\django\db\backends\utils.py", line 79, in execute
    return super(CursorDebugWrapper, self).execute(sql, params)
  File "D:\python\2.7\setuppath\lib\site-packages\django\db\backends\utils.py", line 64, in execute
    return self.cursor.execute(sql, params)
  File "D:\python\2.7\setuppath\lib\site-packages\django\db\utils.py", line 94, in __exit__
    six.reraise(dj_exc_type, dj_exc_value, traceback)
  File "D:\python\2.7\setuppath\lib\site-packages\django\db\backends\utils.py", line 64, in execute
    return self.cursor.execute(sql, params)
  File "D:\python\2.7\setuppath\lib\site-packages\django\db\backends\sqlite3\base.py", line 337, in execute
    return Database.Cursor.execute(self, query, params)
OperationalError: no such table: django_session
2017-04-28 11:21:43,982 [Thread-8:54812] [django.request:124] [exception:handle_uncaught_exception] [ERROR]- Internal Server Error: /web_hook/check_code
Traceback (most recent call last):
  File "D:\python\2.7\setuppath\lib\site-packages\django\core\handlers\exception.py", line 39, in inner
    response = get_response(request)
  File "D:\python\2.7\setuppath\lib\site-packages\django\utils\deprecation.py", line 138, in __call__
    response = self.process_response(request, response)
  File "D:\python\2.7\setuppath\lib\site-packages\django\contrib\sessions\middleware.py", line 58, in process_response
    request.session.save()
  File "D:\python\2.7\setuppath\lib\site-packages\django\contrib\sessions\backends\db.py", line 81, in save
    return self.create()
  File "D:\python\2.7\setuppath\lib\site-packages\django\contrib\sessions\backends\db.py", line 50, in create
    self._session_key = self._get_new_session_key()
  File "D:\python\2.7\setuppath\lib\site-packages\django\contrib\sessions\backends\base.py", line 164, in _get_new_session_key
    if not self.exists(session_key):
  File "D:\python\2.7\setuppath\lib\site-packages\django\contrib\sessions\backends\db.py", line 46, in exists
    return self.model.objects.filter(session_key=session_key).exists()
  File "D:\python\2.7\setuppath\lib\site-packages\django\db\models\query.py", line 660, in exists
    return self.query.has_results(using=self.db)
  File "D:\python\2.7\setuppath\lib\site-packages\django\db\models\sql\query.py", line 494, in has_results
    return compiler.has_results()
  File "D:\python\2.7\setuppath\lib\site-packages\django\db\models\sql\compiler.py", line 806, in has_results
    return bool(self.execute_sql(SINGLE))
  File "D:\python\2.7\setuppath\lib\site-packages\django\db\models\sql\compiler.py", line 835, in execute_sql
    cursor.execute(sql, params)
  File "D:\python\2.7\setuppath\lib\site-packages\django\db\backends\utils.py", line 79, in execute
    return super(CursorDebugWrapper, self).execute(sql, params)
  File "D:\python\2.7\setuppath\lib\site-packages\django\db\backends\utils.py", line 64, in execute
    return self.cursor.execute(sql, params)
  File "D:\python\2.7\setuppath\lib\site-packages\django\db\utils.py", line 94, in __exit__
    six.reraise(dj_exc_type, dj_exc_value, traceback)
  File "D:\python\2.7\setuppath\lib\site-packages\django\db\backends\utils.py", line 64, in execute
    return self.cursor.execute(sql, params)
  File "D:\python\2.7\setuppath\lib\site-packages\django\db\backends\sqlite3\base.py", line 337, in execute
    return Database.Cursor.execute(self, query, params)
OperationalError: no such table: django_session
2017-04-28 11:25:18,845 [Thread-7:54532] [django.request:124] [exception:handle_uncaught_exception] [ERROR]- Internal Server Error: /web_hook/check_code
Traceback (most recent call last):
  File "D:\python\2.7\setuppath\lib\site-packages\django\core\handlers\exception.py", line 39, in inner
    response = get_response(request)
  File "D:\python\2.7\setuppath\lib\site-packages\django\utils\deprecation.py", line 138, in __call__
    response = self.process_response(request, response)
  File "D:\python\2.7\setuppath\lib\site-packages\django\contrib\sessions\middleware.py", line 58, in process_response
    request.session.save()
  File "D:\python\2.7\setuppath\lib\site-packages\django\contrib\sessions\backends\db.py", line 81, in save
    return self.create()
  File "D:\python\2.7\setuppath\lib\site-packages\django\contrib\sessions\backends\db.py", line 50, in create
    self._session_key = self._get_new_session_key()
  File "D:\python\2.7\setuppath\lib\site-packages\django\contrib\sessions\backends\base.py", line 164, in _get_new_session_key
    if not self.exists(session_key):
  File "D:\python\2.7\setuppath\lib\site-packages\django\contrib\sessions\backends\db.py", line 46, in exists
    return self.model.objects.filter(session_key=session_key).exists()
  File "D:\python\2.7\setuppath\lib\site-packages\django\db\models\query.py", line 660, in exists
    return self.query.has_results(using=self.db)
  File "D:\python\2.7\setuppath\lib\site-packages\django\db\models\sql\query.py", line 494, in has_results
    return compiler.has_results()
  File "D:\python\2.7\setuppath\lib\site-packages\django\db\models\sql\compiler.py", line 806, in has_results
    return bool(self.execute_sql(SINGLE))
  File "D:\python\2.7\setuppath\lib\site-packages\django\db\models\sql\compiler.py", line 835, in execute_sql
    cursor.execute(sql, params)
  File "D:\python\2.7\setuppath\lib\site-packages\django\db\backends\utils.py", line 79, in execute
    return super(CursorDebugWrapper, self).execute(sql, params)
  File "D:\python\2.7\setuppath\lib\site-packages\django\db\backends\utils.py", line 64, in execute
    return self.cursor.execute(sql, params)
  File "D:\python\2.7\setuppath\lib\site-packages\django\db\utils.py", line 94, in __exit__
    six.reraise(dj_exc_type, dj_exc_value, traceback)
  File "D:\python\2.7\setuppath\lib\site-packages\django\db\backends\utils.py", line 64, in execute
    return self.cursor.execute(sql, params)
  File "D:\python\2.7\setuppath\lib\site-packages\django\db\backends\sqlite3\base.py", line 337, in execute
    return Database.Cursor.execute(self, query, params)
OperationalError: no such table: django_session
2017-04-28 11:25:21,117 [Thread-8:55168] [django.request:124] [exception:handle_uncaught_exception] [ERROR]- Internal Server Error: /web_hook/check_code
Traceback (most recent call last):
  File "D:\python\2.7\setuppath\lib\site-packages\django\core\handlers\exception.py", line 39, in inner
    response = get_response(request)
  File "D:\python\2.7\setuppath\lib\site-packages\django\utils\deprecation.py", line 138, in __call__
    response = self.process_response(request, response)
  File "D:\python\2.7\setuppath\lib\site-packages\django\contrib\sessions\middleware.py", line 58, in process_response
    request.session.save()
  File "D:\python\2.7\setuppath\lib\site-packages\django\contrib\sessions\backends\db.py", line 81, in save
    return self.create()
  File "D:\python\2.7\setuppath\lib\site-packages\django\contrib\sessions\backends\db.py", line 50, in create
    self._session_key = self._get_new_session_key()
  File "D:\python\2.7\setuppath\lib\site-packages\django\contrib\sessions\backends\base.py", line 164, in _get_new_session_key
    if not self.exists(session_key):
  File "D:\python\2.7\setuppath\lib\site-packages\django\contrib\sessions\backends\db.py", line 46, in exists
    return self.model.objects.filter(session_key=session_key).exists()
  File "D:\python\2.7\setuppath\lib\site-packages\django\db\models\query.py", line 660, in exists
    return self.query.has_results(using=self.db)
  File "D:\python\2.7\setuppath\lib\site-packages\django\db\models\sql\query.py", line 494, in has_results
    return compiler.has_results()
  File "D:\python\2.7\setuppath\lib\site-packages\django\db\models\sql\compiler.py", line 806, in has_results
    return bool(self.execute_sql(SINGLE))
  File "D:\python\2.7\setuppath\lib\site-packages\django\db\models\sql\compiler.py", line 835, in execute_sql
    cursor.execute(sql, params)
  File "D:\python\2.7\setuppath\lib\site-packages\django\db\backends\utils.py", line 79, in execute
    return super(CursorDebugWrapper, self).execute(sql, params)
  File "D:\python\2.7\setuppath\lib\site-packages\django\db\backends\utils.py", line 64, in execute
    return self.cursor.execute(sql, params)
  File "D:\python\2.7\setuppath\lib\site-packages\django\db\utils.py", line 94, in __exit__
    six.reraise(dj_exc_type, dj_exc_value, traceback)
  File "D:\python\2.7\setuppath\lib\site-packages\django\db\backends\utils.py", line 64, in execute
    return self.cursor.execute(sql, params)
  File "D:\python\2.7\setuppath\lib\site-packages\django\db\backends\sqlite3\base.py", line 337, in execute
    return Database.Cursor.execute(self, query, params)
OperationalError: no such table: django_session
2017-04-28 11:25:22,019 [Thread-9:53104] [django.request:124] [exception:handle_uncaught_exception] [ERROR]- Internal Server Error: /web_hook/check_code
Traceback (most recent call last):
  File "D:\python\2.7\setuppath\lib\site-packages\django\core\handlers\exception.py", line 39, in inner
    response = get_response(request)
  File "D:\python\2.7\setuppath\lib\site-packages\django\utils\deprecation.py", line 138, in __call__
    response = self.process_response(request, response)
  File "D:\python\2.7\setuppath\lib\site-packages\django\contrib\sessions\middleware.py", line 58, in process_response
    request.session.save()
  File "D:\python\2.7\setuppath\lib\site-packages\django\contrib\sessions\backends\db.py", line 81, in save
    return self.create()
  File "D:\python\2.7\setuppath\lib\site-packages\django\contrib\sessions\backends\db.py", line 50, in create
    self._session_key = self._get_new_session_key()
  File "D:\python\2.7\setuppath\lib\site-packages\django\contrib\sessions\backends\base.py", line 164, in _get_new_session_key
    if not self.exists(session_key):
  File "D:\python\2.7\setuppath\lib\site-packages\django\contrib\sessions\backends\db.py", line 46, in exists
    return self.model.objects.filter(session_key=session_key).exists()
  File "D:\python\2.7\setuppath\lib\site-packages\django\db\models\query.py", line 660, in exists
    return self.query.has_results(using=self.db)
  File "D:\python\2.7\setuppath\lib\site-packages\django\db\models\sql\query.py", line 494, in has_results
    return compiler.has_results()
  File "D:\python\2.7\setuppath\lib\site-packages\django\db\models\sql\compiler.py", line 806, in has_results
    return bool(self.execute_sql(SINGLE))
  File "D:\python\2.7\setuppath\lib\site-packages\django\db\models\sql\compiler.py", line 835, in execute_sql
    cursor.execute(sql, params)
  File "D:\python\2.7\setuppath\lib\site-packages\django\db\backends\utils.py", line 79, in execute
    return super(CursorDebugWrapper, self).execute(sql, params)
  File "D:\python\2.7\setuppath\lib\site-packages\django\db\backends\utils.py", line 64, in execute
    return self.cursor.execute(sql, params)
  File "D:\python\2.7\setuppath\lib\site-packages\django\db\utils.py", line 94, in __exit__
    six.reraise(dj_exc_type, dj_exc_value, traceback)
  File "D:\python\2.7\setuppath\lib\site-packages\django\db\backends\utils.py", line 64, in execute
    return self.cursor.execute(sql, params)
  File "D:\python\2.7\setuppath\lib\site-packages\django\db\backends\sqlite3\base.py", line 337, in execute
    return Database.Cursor.execute(self, query, params)
OperationalError: no such table: django_session
2017-04-28 11:25:23,930 [Thread-10:47156] [django.request:124] [exception:handle_uncaught_exception] [ERROR]- Internal Server Error: /web_hook/check_code
Traceback (most recent call last):
  File "D:\python\2.7\setuppath\lib\site-packages\django\core\handlers\exception.py", line 39, in inner
    response = get_response(request)
  File "D:\python\2.7\setuppath\lib\site-packages\django\utils\deprecation.py", line 138, in __call__
    response = self.process_response(request, response)
  File "D:\python\2.7\setuppath\lib\site-packages\django\contrib\sessions\middleware.py", line 58, in process_response
    request.session.save()
  File "D:\python\2.7\setuppath\lib\site-packages\django\contrib\sessions\backends\db.py", line 81, in save
    return self.create()
  File "D:\python\2.7\setuppath\lib\site-packages\django\contrib\sessions\backends\db.py", line 50, in create
    self._session_key = self._get_new_session_key()
  File "D:\python\2.7\setuppath\lib\site-packages\django\contrib\sessions\backends\base.py", line 164, in _get_new_session_key
    if not self.exists(session_key):
  File "D:\python\2.7\setuppath\lib\site-packages\django\contrib\sessions\backends\db.py", line 46, in exists
    return self.model.objects.filter(session_key=session_key).exists()
  File "D:\python\2.7\setuppath\lib\site-packages\django\db\models\query.py", line 660, in exists
    return self.query.has_results(using=self.db)
  File "D:\python\2.7\setuppath\lib\site-packages\django\db\models\sql\query.py", line 494, in has_results
    return compiler.has_results()
  File "D:\python\2.7\setuppath\lib\site-packages\django\db\models\sql\compiler.py", line 806, in has_results
    return bool(self.execute_sql(SINGLE))
  File "D:\python\2.7\setuppath\lib\site-packages\django\db\models\sql\compiler.py", line 835, in execute_sql
    cursor.execute(sql, params)
  File "D:\python\2.7\setuppath\lib\site-packages\django\db\backends\utils.py", line 79, in execute
    return super(CursorDebugWrapper, self).execute(sql, params)
  File "D:\python\2.7\setuppath\lib\site-packages\django\db\backends\utils.py", line 64, in execute
    return self.cursor.execute(sql, params)
  File "D:\python\2.7\setuppath\lib\site-packages\django\db\utils.py", line 94, in __exit__
    six.reraise(dj_exc_type, dj_exc_value, traceback)
  File "D:\python\2.7\setuppath\lib\site-packages\django\db\backends\utils.py", line 64, in execute
    return self.cursor.execute(sql, params)
  File "D:\python\2.7\setuppath\lib\site-packages\django\db\backends\sqlite3\base.py", line 337, in execute
    return Database.Cursor.execute(self, query, params)
OperationalError: no such table: django_session
2017-04-28 11:26:38,740 [Thread-7:54708] [django.request:124] [exception:handle_uncaught_exception] [ERROR]- Internal Server Error: /web_hook/check_code
Traceback (most recent call last):
  File "D:\python\2.7\setuppath\lib\site-packages\django\core\handlers\exception.py", line 39, in inner
    response = get_response(request)
  File "D:\python\2.7\setuppath\lib\site-packages\django\utils\deprecation.py", line 138, in __call__
    response = self.process_response(request, response)
  File "D:\python\2.7\setuppath\lib\site-packages\django\contrib\sessions\middleware.py", line 58, in process_response
    request.session.save()
  File "D:\python\2.7\setuppath\lib\site-packages\django\contrib\sessions\backends\db.py", line 81, in save
    return self.create()
  File "D:\python\2.7\setuppath\lib\site-packages\django\contrib\sessions\backends\db.py", line 50, in create
    self._session_key = self._get_new_session_key()
  File "D:\python\2.7\setuppath\lib\site-packages\django\contrib\sessions\backends\base.py", line 164, in _get_new_session_key
    if not self.exists(session_key):
  File "D:\python\2.7\setuppath\lib\site-packages\django\contrib\sessions\backends\db.py", line 46, in exists
    return self.model.objects.filter(session_key=session_key).exists()
  File "D:\python\2.7\setuppath\lib\site-packages\django\db\models\query.py", line 660, in exists
    return self.query.has_results(using=self.db)
  File "D:\python\2.7\setuppath\lib\site-packages\django\db\models\sql\query.py", line 494, in has_results
    return compiler.has_results()
  File "D:\python\2.7\setuppath\lib\site-packages\django\db\models\sql\compiler.py", line 806, in has_results
    return bool(self.execute_sql(SINGLE))
  File "D:\python\2.7\setuppath\lib\site-packages\django\db\models\sql\compiler.py", line 824, in execute_sql
    sql, params = self.as_sql()
  File "D:\python\2.7\setuppath\lib\site-packages\django\db\models\sql\compiler.py", line 374, in as_sql
    from_, f_params = self.get_from_clause()
  File "D:\python\2.7\setuppath\lib\site-packages\django\db\models\sql\compiler.py", line 612, in get_from_clause
    clause_sql, clause_params = self.compile(from_clause)
  File "D:\python\2.7\setuppath\lib\site-packages\django\db\models\sql\compiler.py", line 353, in compile
    sql, params = node.as_sql(self, self.connection)
  File "D:\python\2.7\setuppath\lib\site-packages\django\db\models\sql\datastructures.py", line 146, in as_sql
    base_sql = compiler.quote_name_unless_alias(self.table_name)
  File "D:\python\2.7\setuppath\lib\site-packages\django\db\models\sql\compiler.py", line 344, in quote_name_unless_alias
    r = self.connection.ops.quote_name(name)
  File "D:\python\2.7\setuppath\lib\site-packages\django\db\backends\dummy\base.py", line 21, in complain
    raise ImproperlyConfigured("settings.DATABASES is improperly configured. "
ImproperlyConfigured: settings.DATABASES is improperly configured. Please supply the ENGINE value. Check settings documentation for more details.
2017-04-28 12:56:02,142 [Thread-7:54428] [django.request:124] [exception:handle_uncaught_exception] [ERROR]- Internal Server Error: /web_hook/check_code
Traceback (most recent call last):
  File "D:\python\2.7\setuppath\lib\site-packages\django\core\handlers\exception.py", line 39, in inner
    response = get_response(request)
  File "D:\python\2.7\setuppath\lib\site-packages\django\utils\deprecation.py", line 138, in __call__
    response = self.process_response(request, response)
  File "D:\python\2.7\setuppath\lib\site-packages\django\contrib\sessions\middleware.py", line 58, in process_response
    request.session.save()
  File "D:\python\2.7\setuppath\lib\site-packages\django\contrib\sessions\backends\db.py", line 81, in save
    return self.create()
  File "D:\python\2.7\setuppath\lib\site-packages\django\contrib\sessions\backends\db.py", line 50, in create
    self._session_key = self._get_new_session_key()
  File "D:\python\2.7\setuppath\lib\site-packages\django\contrib\sessions\backends\base.py", line 164, in _get_new_session_key
    if not self.exists(session_key):
  File "D:\python\2.7\setuppath\lib\site-packages\django\contrib\sessions\backends\db.py", line 46, in exists
    return self.model.objects.filter(session_key=session_key).exists()
  File "D:\python\2.7\setuppath\lib\site-packages\django\db\models\query.py", line 660, in exists
    return self.query.has_results(using=self.db)
  File "D:\python\2.7\setuppath\lib\site-packages\django\db\models\sql\query.py", line 494, in has_results
    return compiler.has_results()
  File "D:\python\2.7\setuppath\lib\site-packages\django\db\models\sql\compiler.py", line 806, in has_results
    return bool(self.execute_sql(SINGLE))
  File "D:\python\2.7\setuppath\lib\site-packages\django\db\models\sql\compiler.py", line 824, in execute_sql
    sql, params = self.as_sql()
  File "D:\python\2.7\setuppath\lib\site-packages\django\db\models\sql\compiler.py", line 374, in as_sql
    from_, f_params = self.get_from_clause()
  File "D:\python\2.7\setuppath\lib\site-packages\django\db\models\sql\compiler.py", line 612, in get_from_clause
    clause_sql, clause_params = self.compile(from_clause)
  File "D:\python\2.7\setuppath\lib\site-packages\django\db\models\sql\compiler.py", line 353, in compile
    sql, params = node.as_sql(self, self.connection)
  File "D:\python\2.7\setuppath\lib\site-packages\django\db\models\sql\datastructures.py", line 146, in as_sql
    base_sql = compiler.quote_name_unless_alias(self.table_name)
  File "D:\python\2.7\setuppath\lib\site-packages\django\db\models\sql\compiler.py", line 344, in quote_name_unless_alias
    r = self.connection.ops.quote_name(name)
  File "D:\python\2.7\setuppath\lib\site-packages\django\db\backends\dummy\base.py", line 21, in complain
    raise ImproperlyConfigured("settings.DATABASES is improperly configured. "
ImproperlyConfigured: settings.DATABASES is improperly configured. Please supply the ENGINE value. Check settings documentation for more details.
2017-04-28 12:56:03,538 [Thread-8:54928] [django.request:124] [exception:handle_uncaught_exception] [ERROR]- Internal Server Error: /web_hook/check_code
Traceback (most recent call last):
  File "D:\python\2.7\setuppath\lib\site-packages\django\core\handlers\exception.py", line 39, in inner
    response = get_response(request)
  File "D:\python\2.7\setuppath\lib\site-packages\django\utils\deprecation.py", line 138, in __call__
    response = self.process_response(request, response)
  File "D:\python\2.7\setuppath\lib\site-packages\django\contrib\sessions\middleware.py", line 58, in process_response
    request.session.save()
  File "D:\python\2.7\setuppath\lib\site-packages\django\contrib\sessions\backends\db.py", line 81, in save
    return self.create()
  File "D:\python\2.7\setuppath\lib\site-packages\django\contrib\sessions\backends\db.py", line 50, in create
    self._session_key = self._get_new_session_key()
  File "D:\python\2.7\setuppath\lib\site-packages\django\contrib\sessions\backends\base.py", line 164, in _get_new_session_key
    if not self.exists(session_key):
  File "D:\python\2.7\setuppath\lib\site-packages\django\contrib\sessions\backends\db.py", line 46, in exists
    return self.model.objects.filter(session_key=session_key).exists()
  File "D:\python\2.7\setuppath\lib\site-packages\django\db\models\query.py", line 660, in exists
    return self.query.has_results(using=self.db)
  File "D:\python\2.7\setuppath\lib\site-packages\django\db\models\sql\query.py", line 494, in has_results
    return compiler.has_results()
  File "D:\python\2.7\setuppath\lib\site-packages\django\db\models\sql\compiler.py", line 806, in has_results
    return bool(self.execute_sql(SINGLE))
  File "D:\python\2.7\setuppath\lib\site-packages\django\db\models\sql\compiler.py", line 824, in execute_sql
    sql, params = self.as_sql()
  File "D:\python\2.7\setuppath\lib\site-packages\django\db\models\sql\compiler.py", line 374, in as_sql
    from_, f_params = self.get_from_clause()
  File "D:\python\2.7\setuppath\lib\site-packages\django\db\models\sql\compiler.py", line 612, in get_from_clause
    clause_sql, clause_params = self.compile(from_clause)
  File "D:\python\2.7\setuppath\lib\site-packages\django\db\models\sql\compiler.py", line 353, in compile
    sql, params = node.as_sql(self, self.connection)
  File "D:\python\2.7\setuppath\lib\site-packages\django\db\models\sql\datastructures.py", line 146, in as_sql
    base_sql = compiler.quote_name_unless_alias(self.table_name)
  File "D:\python\2.7\setuppath\lib\site-packages\django\db\models\sql\compiler.py", line 344, in quote_name_unless_alias
    r = self.connection.ops.quote_name(name)
  File "D:\python\2.7\setuppath\lib\site-packages\django\db\backends\dummy\base.py", line 21, in complain
    raise ImproperlyConfigured("settings.DATABASES is improperly configured. "
ImproperlyConfigured: settings.DATABASES is improperly configured. Please supply the ENGINE value. Check settings documentation for more details.
2017-04-28 12:56:36,094 [Thread-7:51860] [django.request:124] [exception:handle_uncaught_exception] [ERROR]- Internal Server Error: /web_hook/check_code
Traceback (most recent call last):
  File "D:\python\2.7\setuppath\lib\site-packages\django\core\handlers\exception.py", line 39, in inner
    response = get_response(request)
  File "D:\python\2.7\setuppath\lib\site-packages\django\utils\deprecation.py", line 138, in __call__
    response = self.process_response(request, response)
  File "D:\python\2.7\setuppath\lib\site-packages\django\contrib\sessions\middleware.py", line 58, in process_response
    request.session.save()
  File "D:\python\2.7\setuppath\lib\site-packages\django\contrib\sessions\backends\db.py", line 81, in save
    return self.create()
  File "D:\python\2.7\setuppath\lib\site-packages\django\contrib\sessions\backends\db.py", line 50, in create
    self._session_key = self._get_new_session_key()
  File "D:\python\2.7\setuppath\lib\site-packages\django\contrib\sessions\backends\base.py", line 164, in _get_new_session_key
    if not self.exists(session_key):
  File "D:\python\2.7\setuppath\lib\site-packages\django\contrib\sessions\backends\db.py", line 46, in exists
    return self.model.objects.filter(session_key=session_key).exists()
  File "D:\python\2.7\setuppath\lib\site-packages\django\db\models\query.py", line 660, in exists
    return self.query.has_results(using=self.db)
  File "D:\python\2.7\setuppath\lib\site-packages\django\db\models\sql\query.py", line 494, in has_results
    return compiler.has_results()
  File "D:\python\2.7\setuppath\lib\site-packages\django\db\models\sql\compiler.py", line 806, in has_results
    return bool(self.execute_sql(SINGLE))
  File "D:\python\2.7\setuppath\lib\site-packages\django\db\models\sql\compiler.py", line 835, in execute_sql
    cursor.execute(sql, params)
  File "D:\python\2.7\setuppath\lib\site-packages\django\db\backends\utils.py", line 79, in execute
    return super(CursorDebugWrapper, self).execute(sql, params)
  File "D:\python\2.7\setuppath\lib\site-packages\django\db\backends\utils.py", line 64, in execute
    return self.cursor.execute(sql, params)
  File "D:\python\2.7\setuppath\lib\site-packages\django\db\utils.py", line 94, in __exit__
    six.reraise(dj_exc_type, dj_exc_value, traceback)
  File "D:\python\2.7\setuppath\lib\site-packages\django\db\backends\utils.py", line 64, in execute
    return self.cursor.execute(sql, params)
  File "D:\python\2.7\setuppath\lib\site-packages\django\db\backends\sqlite3\base.py", line 337, in execute
    return Database.Cursor.execute(self, query, params)
OperationalError: no such table: django_session
2017-04-28 13:00:19,802 [Thread-7:40872] [django.request:124] [exception:handle_uncaught_exception] [ERROR]- Internal Server Error: /web_hook/check_code
Traceback (most recent call last):
  File "D:\python\2.7\setuppath\lib\site-packages\django\core\handlers\exception.py", line 39, in inner
    response = get_response(request)
  File "D:\python\2.7\setuppath\lib\site-packages\django\core\handlers\base.py", line 187, in _get_response
    response = self.process_exception_by_middleware(e, request)
  File "D:\python\2.7\setuppath\lib\site-packages\django\core\handlers\base.py", line 185, in _get_response
    response = wrapped_callback(request, *callback_args, **callback_kwargs)
  File "E:/my/projects/python/git_web_hooks\apps\views.py", line 40, in check_code
    check_display = my_captcha.display()
  File "E:/my/projects/python/git_web_hooks\apps\ext\Captcha.py", line 87, in display
    self.django_request.session[self.session_key] = ''
  File "D:\python\2.7\setuppath\lib\site-packages\django\contrib\sessions\backends\base.py", line 60, in __setitem__
    self._session[key] = value
  File "D:\python\2.7\setuppath\lib\site-packages\django\contrib\sessions\backends\base.py", line 207, in _get_session
    self._session_cache = self.load()
  File "D:\python\2.7\setuppath\lib\site-packages\django\contrib\sessions\backends\db.py", line 35, in load
    expire_date__gt=timezone.now()
  File "D:\python\2.7\setuppath\lib\site-packages\django\db\models\manager.py", line 85, in manager_method
    return getattr(self.get_queryset(), name)(*args, **kwargs)
  File "D:\python\2.7\setuppath\lib\site-packages\django\db\models\query.py", line 379, in get
    num = len(clone)
  File "D:\python\2.7\setuppath\lib\site-packages\django\db\models\query.py", line 238, in __len__
    self._fetch_all()
  File "D:\python\2.7\setuppath\lib\site-packages\django\db\models\query.py", line 1087, in _fetch_all
    self._result_cache = list(self.iterator())
  File "D:\python\2.7\setuppath\lib\site-packages\django\db\models\query.py", line 54, in __iter__
    results = compiler.execute_sql()
  File "D:\python\2.7\setuppath\lib\site-packages\django\db\models\sql\compiler.py", line 835, in execute_sql
    cursor.execute(sql, params)
  File "D:\python\2.7\setuppath\lib\site-packages\django\db\backends\utils.py", line 79, in execute
    return super(CursorDebugWrapper, self).execute(sql, params)
  File "D:\python\2.7\setuppath\lib\site-packages\django\db\backends\utils.py", line 64, in execute
    return self.cursor.execute(sql, params)
  File "D:\python\2.7\setuppath\lib\site-packages\django\db\utils.py", line 94, in __exit__
    six.reraise(dj_exc_type, dj_exc_value, traceback)
  File "D:\python\2.7\setuppath\lib\site-packages\django\db\backends\utils.py", line 64, in execute
    return self.cursor.execute(sql, params)
  File "D:\python\2.7\setuppath\lib\site-packages\django\db\backends\sqlite3\base.py", line 337, in execute
    return Database.Cursor.execute(self, query, params)
OperationalError: no such table: django_session
2017-04-28 13:01:25,479 [Thread-7:55284] [django.request:124] [exception:handle_uncaught_exception] [ERROR]- Internal Server Error: /web_hook/check_code
Traceback (most recent call last):
  File "D:\python\2.7\setuppath\lib\site-packages\django\core\handlers\exception.py", line 39, in inner
    response = get_response(request)
  File "D:\python\2.7\setuppath\lib\site-packages\django\core\handlers\base.py", line 187, in _get_response
    response = self.process_exception_by_middleware(e, request)
  File "D:\python\2.7\setuppath\lib\site-packages\django\core\handlers\base.py", line 185, in _get_response
    response = wrapped_callback(request, *callback_args, **callback_kwargs)
  File "E:/my/projects/python/git_web_hooks\apps\views.py", line 40, in check_code
    check_display = my_captcha.display()
  File "E:/my/projects/python/git_web_hooks\apps\ext\Captcha.py", line 87, in display
    self.django_request.session[self.session_key] = ''
  File "D:\python\2.7\setuppath\lib\site-packages\django\contrib\sessions\backends\base.py", line 60, in __setitem__
    self._session[key] = value
  File "D:\python\2.7\setuppath\lib\site-packages\django\contrib\sessions\backends\base.py", line 207, in _get_session
    self._session_cache = self.load()
  File "D:\python\2.7\setuppath\lib\site-packages\django\contrib\sessions\backends\db.py", line 35, in load
    expire_date__gt=timezone.now()
  File "D:\python\2.7\setuppath\lib\site-packages\django\db\models\manager.py", line 85, in manager_method
    return getattr(self.get_queryset(), name)(*args, **kwargs)
  File "D:\python\2.7\setuppath\lib\site-packages\django\db\models\query.py", line 379, in get
    num = len(clone)
  File "D:\python\2.7\setuppath\lib\site-packages\django\db\models\query.py", line 238, in __len__
    self._fetch_all()
  File "D:\python\2.7\setuppath\lib\site-packages\django\db\models\query.py", line 1087, in _fetch_all
    self._result_cache = list(self.iterator())
  File "D:\python\2.7\setuppath\lib\site-packages\django\db\models\query.py", line 54, in __iter__
    results = compiler.execute_sql()
  File "D:\python\2.7\setuppath\lib\site-packages\django\db\models\sql\compiler.py", line 835, in execute_sql
    cursor.execute(sql, params)
  File "D:\python\2.7\setuppath\lib\site-packages\django\db\backends\utils.py", line 79, in execute
    return super(CursorDebugWrapper, self).execute(sql, params)
  File "D:\python\2.7\setuppath\lib\site-packages\django\db\backends\utils.py", line 64, in execute
    return self.cursor.execute(sql, params)
  File "D:\python\2.7\setuppath\lib\site-packages\django\db\utils.py", line 94, in __exit__
    six.reraise(dj_exc_type, dj_exc_value, traceback)
  File "D:\python\2.7\setuppath\lib\site-packages\django\db\backends\utils.py", line 64, in execute
    return self.cursor.execute(sql, params)
  File "D:\python\2.7\setuppath\lib\site-packages\django\db\backends\sqlite3\base.py", line 337, in execute
    return Database.Cursor.execute(self, query, params)
OperationalError: no such table: django_session
2017-04-28 13:01:58,844 [Thread-7:54356] [django.request:124] [exception:handle_uncaught_exception] [ERROR]- Internal Server Error: /web_hook/check_code
Traceback (most recent call last):
  File "D:\python\2.7\setuppath\lib\site-packages\django\core\handlers\exception.py", line 39, in inner
    response = get_response(request)
  File "D:\python\2.7\setuppath\lib\site-packages\django\core\handlers\base.py", line 187, in _get_response
    response = self.process_exception_by_middleware(e, request)
  File "D:\python\2.7\setuppath\lib\site-packages\django\core\handlers\base.py", line 185, in _get_response
    response = wrapped_callback(request, *callback_args, **callback_kwargs)
  File "E:/my/projects/python/git_web_hooks\apps\views.py", line 40, in check_code
    check_display = my_captcha.display()
  File "E:/my/projects/python/git_web_hooks\apps\ext\Captcha.py", line 87, in display
    self.django_request.session[self.session_key] = ''
  File "D:\python\2.7\setuppath\lib\site-packages\django\contrib\sessions\backends\base.py", line 60, in __setitem__
    self._session[key] = value
  File "D:\python\2.7\setuppath\lib\site-packages\django\contrib\sessions\backends\base.py", line 207, in _get_session
    self._session_cache = self.load()
  File "D:\python\2.7\setuppath\lib\site-packages\django\contrib\sessions\backends\db.py", line 35, in load
    expire_date__gt=timezone.now()
  File "D:\python\2.7\setuppath\lib\site-packages\django\db\models\manager.py", line 85, in manager_method
    return getattr(self.get_queryset(), name)(*args, **kwargs)
  File "D:\python\2.7\setuppath\lib\site-packages\django\db\models\query.py", line 379, in get
    num = len(clone)
  File "D:\python\2.7\setuppath\lib\site-packages\django\db\models\query.py", line 238, in __len__
    self._fetch_all()
  File "D:\python\2.7\setuppath\lib\site-packages\django\db\models\query.py", line 1087, in _fetch_all
    self._result_cache = list(self.iterator())
  File "D:\python\2.7\setuppath\lib\site-packages\django\db\models\query.py", line 54, in __iter__
    results = compiler.execute_sql()
  File "D:\python\2.7\setuppath\lib\site-packages\django\db\models\sql\compiler.py", line 835, in execute_sql
    cursor.execute(sql, params)
  File "D:\python\2.7\setuppath\lib\site-packages\django\db\backends\utils.py", line 79, in execute
    return super(CursorDebugWrapper, self).execute(sql, params)
  File "D:\python\2.7\setuppath\lib\site-packages\django\db\backends\utils.py", line 64, in execute
    return self.cursor.execute(sql, params)
  File "D:\python\2.7\setuppath\lib\site-packages\django\db\utils.py", line 94, in __exit__
    six.reraise(dj_exc_type, dj_exc_value, traceback)
  File "D:\python\2.7\setuppath\lib\site-packages\django\db\backends\utils.py", line 64, in execute
    return self.cursor.execute(sql, params)
  File "D:\python\2.7\setuppath\lib\site-packages\django\db\backends\sqlite3\base.py", line 337, in execute
    return Database.Cursor.execute(self, query, params)
OperationalError: no such table: django_session
2017-04-28 13:37:32,216 [Thread-14:55248] [django.request:124] [exception:handle_uncaught_exception] [ERROR]- Internal Server Error: /web_hook/check_code
Traceback (most recent call last):
  File "D:\python\2.7\setuppath\lib\site-packages\django\core\handlers\exception.py", line 39, in inner
    response = get_response(request)
  File "D:\python\2.7\setuppath\lib\site-packages\django\core\handlers\base.py", line 187, in _get_response
    response = self.process_exception_by_middleware(e, request)
  File "D:\python\2.7\setuppath\lib\site-packages\django\core\handlers\base.py", line 185, in _get_response
    response = wrapped_callback(request, *callback_args, **callback_kwargs)
  File "E:/my/projects/python/git_web_hooks\apps\views.py", line 41, in check_code
    return HttpResponse(''.join(('data:image/gif;base64,', check_display)), mimetype="image/gif")
  File "D:\python\2.7\setuppath\lib\site-packages\django\http\response.py", line 291, in __init__
    super(HttpResponse, self).__init__(*args, **kwargs)
TypeError: __init__() got an unexpected keyword argument 'mimetype'
2017-04-28 13:37:45,990 [Thread-19:56308] [django.request:124] [exception:handle_uncaught_exception] [ERROR]- Internal Server Error: /web_hook/check_code
Traceback (most recent call last):
  File "D:\python\2.7\setuppath\lib\site-packages\django\core\handlers\exception.py", line 39, in inner
    response = get_response(request)
  File "D:\python\2.7\setuppath\lib\site-packages\django\core\handlers\base.py", line 187, in _get_response
    response = self.process_exception_by_middleware(e, request)
  File "D:\python\2.7\setuppath\lib\site-packages\django\core\handlers\base.py", line 185, in _get_response
    response = wrapped_callback(request, *callback_args, **callback_kwargs)
  File "E:/my/projects/python/git_web_hooks\apps\views.py", line 41, in check_code
    return HttpResponse(''.join(('data:image/gif;base64,', check_display)), mimetype="image/gif")
  File "D:\python\2.7\setuppath\lib\site-packages\django\http\response.py", line 291, in __init__
    super(HttpResponse, self).__init__(*args, **kwargs)
TypeError: __init__() got an unexpected keyword argument 'mimetype'
2017-04-28 13:38:47,650 [Thread-25:55896] [django.request:124] [exception:handle_uncaught_exception] [ERROR]- Internal Server Error: /web_hook/check_code
Traceback (most recent call last):
  File "D:\python\2.7\setuppath\lib\site-packages\django\core\handlers\exception.py", line 39, in inner
    response = get_response(request)
  File "D:\python\2.7\setuppath\lib\site-packages\django\core\handlers\base.py", line 187, in _get_response
    response = self.process_exception_by_middleware(e, request)
  File "D:\python\2.7\setuppath\lib\site-packages\django\core\handlers\base.py", line 185, in _get_response
    response = wrapped_callback(request, *callback_args, **callback_kwargs)
  File "E:/my/projects/python/git_web_hooks\apps\views.py", line 41, in check_code
    return HttpResponse(''.join(('data:image/gif;base64,', check_display)), mimetype="image/gif")
  File "D:\python\2.7\setuppath\lib\site-packages\django\http\response.py", line 291, in __init__
    super(HttpResponse, self).__init__(*args, **kwargs)
TypeError: __init__() got an unexpected keyword argument 'mimetype'
2017-04-28 14:15:29,151 [Thread-14:56836] [django.request:152] [base:get_response] [WARNING]- Not Found: /web_hook/R0lGODdhlgAeAIcAAAAAAAAAAAAAAAAAAAAAAAAAAAAAAAAAAAAAAAAAAAAAADMAAGYAAJkAAMwAAP8AAAAzADMzAGYzAJkzAMwzAP8zAABmADNmAGZmAJlmAMxmAP9mAACZADOZAGaZAJmZAMyZAP+ZAADMADPMAGbMAJnMAMzMAP/MAAD/ADP/AGb/AJn/AMz/AP//AAAAMzMAM2YAM5kAM8wAM/8AMwAzMzMzM2YzM5kzM8wzM/8zMwBmMzNmM2ZmM5lmM8xmM/9mMwCZMzOZM2aZM5mZM8yZM/+ZMwDMMzPMM2bMM5nMM8zMM//MMwD/MzP/M2b/M5n/M8z/M///MwAAZjMAZmYAZpkAZswAZv8AZgAzZjMzZmYzZpkzZswzZv8zZgBmZjNmZmZmZplmZsxmZv9mZgCZZjOZZmaZZpmZZsyZZv+ZZgDMZjPMZmbMZpnMZszMZv/MZgD/ZjP/Zmb/Zpn/Zsz/Zv//ZgAAmTMAmWYAmZkAmcwAmf8AmQAzmTMzmWYzmZkzmcwzmf8zmQBmmTNmmWZmmZlmmcxmmf9mmQCZmTOZmWaZmZmZmcyZmf+ZmQDMmTPMmWbMmZnMmczMmf/MmQD/mTP/mWb/mZn/mcz/mf//mQAAzDMAzGYAzJkAzMwAzP8AzAAzzDMzzGYzzJkzzMwzzP8zzABmzDNmzGZmzJlmzMxmzP9mzACZzDOZzGaZzJmZzMyZzP+ZzADMzDPMzGbMzJnMzMzMzP/MzAD/zDP/zGb/zJn/zMz/zP//zAAA/zMA/2YA/5kA/8wA//8A/wAz/zMz/2Yz/5kz/8wz//8z/wBm/zNm/2Zm/5lm/8xm//9m/wCZ/zOZ/2aZ/5mZ/8yZ//+Z/wDM/zPM/2bM/5nM/8zM///M/wD//zP//2b//5n//8z//////wAAAAAAAAAAAAAAAAAAAAAAAAAAAAAAAAAAAAAAAAAAAAAAAAAAAAAAAAAAAAAAAAAAAAAAAAAAAAAAAAAAAAAAAAAAAAAAAAAAAAAAAAAAAAAAAAAAAAAAACwAAAAAlgAeAEAI/wDDgQsHLhy4cODCgQsHLhwyT8iQgQsHLhy4cODCgQsHLhy4cODCgQsHLhy4cODCgQsHLhy4cODCgQsHLhy4cODCgQsHLhy4cODCgQsHLhy4cODCgQsHLhy4cODCgQsHLhy4cODCgQsHLhy4cODCgQsHLhy4cODCgQsHLhy4cODCgQsHLhy4cODCgQsHLhy4cODCgQsHLhy4cODCgQsHLhy4cODCgQsHLhy4cOC2gQvXC1wvVFLspOoFrhe4XuAWAVhkKxy4XuHAbesFrhe4cNvA9QIXDlwvcL3AhQO3DVy4Bg3AhQMXDly4cODC9QLXC1y4XuDCgfOEzFMnGADCh/8Dty0cuHDgGDUI0wtcuF7gtoELB64XuHDgwoUD1wtcOIDgwoELBy4cuF7htoELB64XuHDgwoELBy4cuF7htoFD0yBML1thGjRgBC7cNnDgwvUCFy5cL3C9wNnqY8cOoW3geoELFw5cL3DhwPUCtw1cuF7gtoHrBS4cuF7gwoELB64XuHDgwoELB64Bg3DgwoUDFw4cuF7gwoUDFy7cNnDhgHG6AwAADUp5KeGihIsSJVyUwIUDF64XuHC9wPUKBy4cuHDgwm0DBy5cL3C9wvUC1wtcOHDhwoEL1wtcOHC9wIUTRkoYqXC9tE1owAhcL3C9wvUCFy4cOHDhwIELBy7/HLhe4HqFA9cLXLhwvcCFA9cL3LZw4MKB2wYu3DZw4XqBA9cLXLht4HqBAxcOXC9w4cD12gauF7he4HqBCweuF0BwvcKFA9cLXC9w4cD1AhcOXK9t4ML1AtcLXK9w4HptAxcO3LZe4HptAxcOXC9w4cD1AtcrHLhe4XptAxeuF7ht4MKBCwcuXC9w28CF2wauVzhw4cCFAxeuF7hwvcD12gauVzhwvcCF2wYuHLhw4HqBCwcuXC9wvbaB6wWuVzhw4cCF6wUuXC9w4cD1AheuF7hwwkgJQyaMlDBw4cBtCwcu3DZw4cBtCwcu3DZw4cBtCwcu3DZw4cBtCwcu3DZw/+HAbQsHLtw2cOHAbQsHLtw2cOHAbQsHLtw2cOHAbQsHLtw2cOHAbQsHLtw2cOHAbQsHLtw2cOHAbQsHLtw2cOHAbQsHLtw2cOHAbQsHrhc4cOF6gesVrhchO3Zc9QoHDmC4XuC2gesFDsACcL3A9drWi1JEiZTCgQsHLhy4cODChQMHrkEDcOG2gesFLlwvcL3A9QLXC1y4RQC+8AoXCQCABeDCgeu1DVyvWwwahOsFLlw4cL3A9QLXC1w4YchICUMmDBm4cOE4ieLEyRgncNvAhQsHLhy4beDCgdsGLhy4XuB6hQPX6xaDBg3EgAvXC9y2XuDCgQMXDtw2cL22gf/rBW4buF7gwoUD1wtcuF7gwoHrBa4XME7GgIniZIwTJ2PgwoELBy4cuF7geoFr0ABcuHC9wIXrBa4XuG3geoXrBW4buF7gtoHrBW4buF7gwoED1wtcOHDbeoELB64XuF7gwvUCtw1cL3C9wPUC1ytcL3C9woELd/8+uG3hwoELB5CSwIG4KBk0GK4XuF7geoEL1wscuHDgeoHrBS4cuF7gwoXrBa4XuHDgeoUDt60XuG3gwvUC1wscuHDgtoHrBS5cOHDhwPUCFw5cuHDgwoHrBa7XNnC9wIXrBa7XNnC9tvUCtw1cr3DgtvUCFw5cL3C9wPUKBy5cL3C9wG0DFw7/XK9w28D1AtcLXLhwvLb1AgcuHLhe4cBtA9cLXLhw4LaBCwcuXC9w28D1AtcLXC9w4cBtC9drWy9w28D1AtcrHLhe4MCFA7cNXLht4MBtCwduWzhwvcCFA9cLXC9w4ZB1QiYMmSdkwsD1ArcNXDhw28CFA7cNXDhw28CFA7cNXDhw28CFA7cNXDhw28CFA7cNXDhw28CFA7cNXDhw28CFAwhuG7hw4LaBCwduG7hw4LaBCwduG7hw4LaBCwduG7hw4LaBCwduG7hw4LaBCwduG7hw4LaBCwduG7hw4LaBCwduG7hw4LaBCwduWzhwvcCFCwduGzhbr1D5sROuF7he/+HA9QIDQCsYXuF6gQsHrhe4cODCgeu1DVwvcL3AhQMHLhy4XuDCgesFThgyT8iEIfMELhy4XuDCbQMXDly4cOAY1QADLhy4bT0YMWpwA1w4cOHCgdsGLhy4XuDCbQMXDly4cODCbQMXDly4cODCbQMXDly4cODCbQMXDly4cODCbQMXDly4cODCbQMXDly4cODCgesFDlw4cNt6geulTYodO73A9doGrlc4cIsAAPjSC9y2XuB6geu1DVwvcL3AAdwWDlyvcOC2gQsHrheDBuHAgQsHbls4cL3A9QLXC1yvbeB6gQMDYBEYAAAUhQPXC1w4Bg1ieELmCRkpYeDChf/rBa4XuG3gwvUCF27oNnDhtoHrBa4XuHDhwG0LB25buHDgwIUDty1cOHDgGoAF1wtcgwYMwoELFw7ctl7gwvUC1wtcL3C27OANB64XuHDgetHQwgtMDXDhwPUK1wtcuF7gtvUCtw3ctnDbwoFroHlzAwYNPn9mQGn06HC9toHrBS5cOHDhagAAsCgcuHC9boS5haaBrXC9wAHjxEkUJ2CigHEyFg5cL3DgwoGzY0eKHSl2pNiRYmf7dmTgwoELtw1cOHC9tvUC12tbrzANGtzgFa4XuF7bwIUDtw1cOHC9AIIL1wtcOHDhwvUCF24buF7gtoHrtQ1cuF7geoELFw7/XC9w4XqBCweuF7hw4MJtAxcOHKcGDYCJAsbJGCdj4HqBCweuF7he4MKB6wUuHLhe4MD1Ageu1zZwvcCBCwduWzhw28KB2xYO3LZw4CiFxUWJrB0pdqTYkWJHih23b3uBCweuF7ht4HqBCxeuF7gbjMCF6wWu17Ze4MKB6wUuXC9w4LaBCweuF7he4LaB42SMEzBRxXqBA9cLXDhw4cCFAxcOXLhe4HqBCwcuHLhw4baBCxeu1zZwvcCFA7etF7he4HqB2wauF7he4MKB6wUuHLhe28CF6wVuG7he4HqB29YLXC9w28D1CgeuF7he28D1AtdrG7he23qB6wWuF7he/wDBbQPXC1y4XuC2gQvXC1y4cOB6gQPXoGI4cNvChdsWDly4XuC29QLXCxy4cNvA9doGrte2XuB6gdsGrlc4cOF6gQsHrhe4cOHAhQMXDty2XuC2gQsHrhe4beDCbQMXbhu4XuB6hesFbhu4XuHA9QIXrhe4XuC2hesFblu4XuDCgesFrte2XuC2gesFLhy4cOB6geu1DVyvcL3AbQPXC1wvcNvA9doGLlwvcL22gQsXDtw2cOF6gQvXC1y4XuB6gdsGLhy4XuB6gesFLhy4XuB6bQMXrhe4XuF6gesVrhe4XuB6gQvXSxgpYaSEkRLWK1wvcL3C9QLXK1wvcL3C9f8C1ytcL3C9wvUC1ytcL3C9wvUC1ytcL3C9wvUC1ytcL4DgeoXrBa5XuF7geoXrBa5XuF7geoXrBa5XuF7geoXrBa5XuF7geoXrBa5XuF7geoXrBa5XuF7geoXrBa5XuF7geoXrBa5XuF7geoXrBa5XuF7geoXrBa5XuF7geoEL1wtcL3C9wPUKB65XOF7hwIUD1wtcuHDgeoHrFQ5cL3DhwPUShkwYKWSekPUC1wtcr3C8wvUC1wtcr3C8wvUC1wtcr3C8wvUC1wtcr3C8wvUC1wtcr3C8wvUC1wtcr3C8wvUC1wtcr3C8wvUC1wtcr3C8wvUC1wtcr3C8wvUC1wv/XK9wvML1AtcLXK9wvML1AtcLXK9wvML1AtcLXK9wvML1AtcLXC9w4cKB6wWuV7he4Lb1AtcL3DZw4cCFC2cLAEAAAsOB2wauF7htvcCF6wUuHLhe4MKB6wUuXC9knpCREkZKGClwvcLxCtcLXC9wvcKB6wWuF7he4HqB66XNTLhe4HqBC9PghqRwvcD1AtcLXC9wvcKB6wWuF7he4HqB6wWuF7he4HqB6wWuF7he4HqB6wWuF7he4HqB6wWuF7he4HqB6wWuF7he4HqB6xUOXDhw4XqB6wUunJ3EdgaBCwduG7he2gCEA9cL3DZw4XqB2wYuXC9wvbaB6wUuXDhw/9t6hesFrhe4cL3AhesFrhe4cLzAhUPmCZkwUsJIgesVDlwvQgAARArXC1yvcOHANWgArtc2cL3A9QrXC9y2XuB6geu1DVyvbbzC9QLXaxu4XuB6geu1DVyvbbzC9QLXC+A2cL3A9QLHKEwDhWFs9QrXC1yvbb3AbQMXrhe4XuC2gQvHx46UbOHAhQsHbhsEACtthQPXC1w4cOHCgesFLhy4cL3AbQsHLlwvcL3CgWvQAFyvbb3A9QLXC1y4beDCgQsHrlc4cOEW0YgAAAAYT8hICSPlSc+EMLfAbQMXrhe4XuC2gQvXC1wvcNvA9QLXC1wvcL22gQsHrhe4XuHA9f8C1wtcr229wPUCB65XuAYNwmwLZ6tBgx7hwPUC1wtcOHDhwvUCFw5cOHCv7NjxAy4cuF7gwoHrtU0RAADhwIUDFw7cNnDhwIXbBi5cL3C9wG3rBa4XuF7bGjAI1wtcr3DgeoHbFg5cuHDbwPUCZ6vGAlvgANS31QtcOHC9tIVpAPAGuHDgeoEjJQyZMGTCSCHrBW5bL3C9wPUC1wtcOHDhwvUC1wtcL3C9wPUC1ytcL3C9wPXaFm5RgzDhwIlpwOBGr23geoELB64XuHDgtoELB24bHztSXoUD12sbuHC9wIWzBQBMuHDbwIELBy6cWHDhwlE6izbt2QYNwPUCFw7/XK9t4MKB2wYuHLhw4WwB+Av4r6Je28CFAxcOXIMb4MKB6wUuHLhw4HqBC9drkzFOxkRxEmVHip3RpEdLsSPFTq9tvcD1AtcLXK9w4MKBCwcuHLgbDRrcABcOXDhwvcCF6wUOXDhw28KFe2VHCiFw4baB6wVuGxgANcCE6wWuFzhw4XqB2wauF7hwvcD1AtcLXLgGDRg0YNAgfwMGDRg0ANgg3MBt4CgdRJgQwEJwvcCF2xSjAQMqnEQB42SsF7hw4MKBCweuF7he4ML1AtcrXC9w4cCFAxcOXLhe4HqB6wXOEzJPyEgh8xQOHLhw4MKBY9SgQZhw4LaBCweuF7he/+F6gQMXbhu4PnbsSLFjRwq4cL3A9QIXrhe4cODC9QIXbhu4XuDChesFbhu4XuHA9doGrhe4XuF6gWvQAFwvcL3A9domCpgoTsBEARMFTBQncOE8f94WTjS4cKXD9aKUWrVqXJRcb+sFrhe4XuHs3MaNW4odKXakhAMXrhe4cOF4hQPXCxy4cGEa2AoHLlw4cOC2gesFblsvcOF6gQvXC1w4cL3CgesFbhu4XuDChesFLhy4XuC2gQsHrhe4XtvAAQwHLlwvYJyAieIkyhgnTsbCMWgArhe4cOB6gQsHLlwvcOHAhQPXKxy4cL3AhesFLty2XuDC9QK3rRe4XuDC9f8CFy4cuF7hwPUKFw7ctnDhtoELBy4cuHCUnkKN+tRROHC9woEL1wvctnANbIUDF24bOHDheoHbFq4XuG3gwvUC1yscuHDgwvUCFy5cL3C9tgETBYyTMU6cjHEy1gtcL3DgwoHrBS5cL3C9wPUC1wtcOHDhGjQA1wscuHDgtoELF64XuHDgtoHrBS5cuF7gwoHrBS4cuF7bwoEL1wtcOHDheoHbBi7cNnDhwPUCFy4cuHDgwoHbBi4cuG3hwPUCtw1cL3DhwPXaBi7cNnDbwvXaFqaBIXCU7uOipH8buHC9AILbBi5cuF7gem0DF24buF7hwPUCBy5cL3DhwoHrBa7/V7he4HqB67UNXLhw28D1AtdrG69wvcBtA9cLXDhwvcKBCxduG7hwvcCFA7cNXK9w4baB67UNXLhe4MKB6xUOXLht4MKBCxcOXK9w4HqBCwcuHLhe4baB6wUuHLhw4MJtAxcOXLhe4ML1AretF7he4MKB6wWuF7hw4cI0OBOuF7he4MD1AhcOXDhw4cCF09wLXK9w4MKBCwcuXDhwvcBtA9drG7he4HptA9cLXC9wvcCF6wUuXC9wvcCFC9cLXC9w4XqBCwcuHLht4MKB67UNXLht4HqB2wYuHLhe4MKB6wVuG7he4MKBCwcuHLhe28D1AtcrHLhw4MKB6wUuHLhw/wB7gdsWDlwvcOHAgesFLhy4cOB6gesVrhe4beB6hQPXC1w4cOF6geu1DVy4beDCbQPXC1w4cL3ChQPXC1w4cL3AgQsHblsvcOHA9QIXDly4XuDChQPXa1svcL3CgQsHrhe4XtvAhesFrhe4XuB6gQsXDlw4cL3CgQsHrhe4cODCgQvXCxy4cL3AgQvXC1y4beHAgQvXC1w4cOF6geu1DVw4cL3CgdsGrhe4cOHAhQvXC1w4cL3AhdsGrhe4XuB6gesFLhy4XuC2gQu3DVy4XuB6gQsHLhy4cL3AhdsGLhy4cODC9doGLlwvcNvAhQvXC9w2cL3AhQPXC1w4cNvAhYzrBa5XOHDheoHrta0XuHDgem0D12tbL3DbwoHrBW5bOIDgtoELBy4cuHDgeoELB64XuHDgem0DF24buHDgem0DFw7ctnC9wPUKB64XuHDgwoEL1wtcOHDhem3rBW4buF7heoELB64XuF7heoHbBq5XOHDhwoELBy5cL3C9wE0N1wtcOHDhwPXaBi5cQAA7
2017-05-02 10:40:56,619 [Thread-19:63136] [django.request:152] [base:get_response] [WARNING]- Not Found: /favicon.ico
2017-05-02 10:44:46,269 [Thread-80:63240] [django.request:124] [exception:handle_uncaught_exception] [ERROR]- Internal Server Error: /web_hook/login
Traceback (most recent call last):
  File "D:\python\2.7\setuppath\lib\site-packages\django\core\handlers\exception.py", line 39, in inner
    response = get_response(request)
  File "D:\python\2.7\setuppath\lib\site-packages\django\core\handlers\base.py", line 187, in _get_response
    response = self.process_exception_by_middleware(e, request)
  File "D:\python\2.7\setuppath\lib\site-packages\django\core\handlers\base.py", line 185, in _get_response
    response = wrapped_callback(request, *callback_args, **callback_kwargs)
  File "E:/my/projects/python/git_web_hooks\apps\views.py", line 33, in login
    if not my_captcha.validate(check_code_p):
  File "E:/my/projects/python/git_web_hooks\apps\ext\Captcha.py", line 152, in validate
    return _code.lower() == str(code).lower()
UnicodeEncodeError: 'ascii' codec can't encode characters in position 0-2: ordinal not in range(128)
2017-05-02 10:45:43,984 [Thread-92:63020] [django.request:124] [exception:handle_uncaught_exception] [ERROR]- Internal Server Error: /web_hook/login
Traceback (most recent call last):
  File "D:\python\2.7\setuppath\lib\site-packages\django\core\handlers\exception.py", line 39, in inner
    response = get_response(request)
  File "D:\python\2.7\setuppath\lib\site-packages\django\core\handlers\base.py", line 187, in _get_response
    response = self.process_exception_by_middleware(e, request)
  File "D:\python\2.7\setuppath\lib\site-packages\django\core\handlers\base.py", line 185, in _get_response
    response = wrapped_callback(request, *callback_args, **callback_kwargs)
  File "E:/my/projects/python/git_web_hooks\apps\views.py", line 33, in login
    if not my_captcha.validate(check_code_p):
  File "E:/my/projects/python/git_web_hooks\apps\ext\Captcha.py", line 152, in validate
    return _code.lower() == str(code).lower()
UnicodeEncodeError: 'ascii' codec can't encode characters in position 0-2: ordinal not in range(128)
2017-05-02 10:52:45,448 [Thread-7:58428] [django.request:124] [exception:handle_uncaught_exception] [ERROR]- Internal Server Error: /web_hook/login
Traceback (most recent call last):
  File "D:\python\2.7\setuppath\lib\site-packages\django\core\handlers\exception.py", line 39, in inner
    response = get_response(request)
  File "D:\python\2.7\setuppath\lib\site-packages\django\core\handlers\base.py", line 187, in _get_response
    response = self.process_exception_by_middleware(e, request)
  File "D:\python\2.7\setuppath\lib\site-packages\django\core\handlers\base.py", line 185, in _get_response
    response = wrapped_callback(request, *callback_args, **callback_kwargs)
  File "E:/my/projects/python/git_web_hooks\apps\views.py", line 34, in login
    if not my_captcha.validate(check_code_p):
  File "E:/my/projects/python/git_web_hooks\apps\ext\Captcha.py", line 152, in validate
    return _code.lower() == str(code).lower()
UnicodeEncodeError: 'ascii' codec can't encode characters in position 0-2: ordinal not in range(128)
2017-05-02 19:03:06,727 [Thread-8:68112] [django.request:124] [exception:handle_uncaught_exception] [ERROR]- Internal Server Error: /admin/index
Traceback (most recent call last):
  File "D:\python\2.7\setuppath\lib\site-packages\django\core\handlers\exception.py", line 39, in inner
    response = get_response(request)
  File "D:\python\2.7\setuppath\lib\site-packages\django\core\handlers\base.py", line 187, in _get_response
    response = self.process_exception_by_middleware(e, request)
  File "D:\python\2.7\setuppath\lib\site-packages\django\core\handlers\base.py", line 185, in _get_response
    response = wrapped_callback(request, *callback_args, **callback_kwargs)
  File "E:/my/projects/python/git_web_hooks\apps\views_admin.py", line 10, in index
    check_result = Common.check_login(request, True)
  File "E:/my/projects/python/git_web_hooks\apps\ext\Common.py", line 20, in check_login
    my_user_auth = UserAuth(request)
TypeError: 'module' object is not callable
2017-05-02 19:03:07,394 [Thread-9:68148] [django.request:152] [base:get_response] [WARNING]- Not Found: /favicon.ico
2017-05-03 14:03:03,216 [Thread-22:69096] [django.request:152] [base:get_response] [WARNING]- Not Found: /admin/static/h-ui/css/H-ui.min.css
2017-05-03 14:03:03,223 [Thread-23:68924] [django.request:152] [base:get_response] [WARNING]- Not Found: /admin/static/h-ui.admin/css/H-ui.admin.css
2017-05-03 14:03:03,226 [Thread-24:68944] [django.request:152] [base:get_response] [WARNING]- Not Found: /admin/lib/Hui-iconfont/1.0.8/iconfont.css
2017-05-03 14:03:03,246 [Thread-26:65948] [django.request:152] [base:get_response] [WARNING]- Not Found: /admin/static/h-ui.admin/css/style.css
2017-05-03 14:03:03,253 [Thread-25:65672] [django.request:152] [base:get_response] [WARNING]- Not Found: /admin/static/h-ui.admin/skin/default/skin.css
2017-05-03 14:03:03,263 [Thread-27:68520] [django.request:152] [base:get_response] [WARNING]- Not Found: /admin/welcome.html
2017-05-03 14:03:03,556 [Thread-28:66500] [django.request:152] [base:get_response] [WARNING]- Not Found: /admin/lib/jquery/1.9.1/jquery.min.js
2017-05-03 14:03:03,578 [Thread-29:69552] [django.request:152] [base:get_response] [WARNING]- Not Found: /admin/lib/layer/2.4/layer.js
2017-05-03 14:03:03,582 [Thread-30:61404] [django.request:152] [base:get_response] [WARNING]- Not Found: /admin/static/h-ui/js/H-ui.min.js
2017-05-03 14:03:03,592 [Thread-31:66996] [django.request:152] [base:get_response] [WARNING]- Not Found: /admin/static/h-ui.admin/js/H-ui.admin.js
2017-05-03 14:03:03,615 [Thread-32:69608] [django.request:152] [base:get_response] [WARNING]- Not Found: /admin/lib/jquery.contextmenu/jquery.contextmenu.r2.js
2017-05-03 14:04:52,815 [Thread-35:68876] [django.request:152] [base:get_response] [WARNING]- Not Found: /admin/static/h-ui/css/H-ui.min.css
2017-05-03 14:04:52,834 [Thread-36:65472] [django.request:152] [base:get_response] [WARNING]- Not Found: /admin/static/h-ui.admin/css/H-ui.admin.css
2017-05-03 14:04:52,858 [Thread-37:59092] [django.request:152] [base:get_response] [WARNING]- Not Found: /admin/lib/Hui-iconfont/1.0.8/iconfont.css
2017-05-03 14:04:52,881 [Thread-38:66964] [django.request:152] [base:get_response] [WARNING]- Not Found: /admin/static/h-ui.admin/skin/default/skin.css
2017-05-03 14:04:52,894 [Thread-39:68692] [django.request:152] [base:get_response] [WARNING]- Not Found: /admin/static/h-ui.admin/css/style.css
2017-05-03 14:04:53,062 [Thread-40:68684] [django.request:152] [base:get_response] [WARNING]- Not Found: /admin/welcome.html
2017-05-03 14:04:53,076 [Thread-41:69128] [django.request:152] [base:get_response] [WARNING]- Not Found: /admin/lib/jquery/1.9.1/jquery.min.js
2017-05-03 14:04:53,115 [Thread-42:68628] [django.request:152] [base:get_response] [WARNING]- Not Found: /admin/lib/layer/2.4/layer.js
2017-05-03 14:04:53,151 [Thread-43:68888] [django.request:152] [base:get_response] [WARNING]- Not Found: /admin/static/h-ui/js/H-ui.min.js
2017-05-03 14:04:53,187 [Thread-44:69568] [django.request:152] [base:get_response] [WARNING]- Not Found: /admin/static/h-ui.admin/js/H-ui.admin.js
2017-05-03 14:04:53,243 [Thread-45:67736] [django.request:152] [base:get_response] [WARNING]- Not Found: /admin/lib/jquery.contextmenu/jquery.contextmenu.r2.js
2017-05-03 14:06:08,025 [Thread-48:69760] [django.request:152] [base:get_response] [WARNING]- Not Found: /admin/static/h-ui/css/H-ui.min.css
2017-05-03 14:06:08,171 [Thread-49:69768] [django.request:152] [base:get_response] [WARNING]- Not Found: /admin/static/h-ui.admin/css/H-ui.admin.css
2017-05-03 14:06:08,186 [Thread-51:69780] [django.request:152] [base:get_response] [WARNING]- Not Found: /admin/static/h-ui.admin/skin/default/skin.css
2017-05-03 14:06:08,190 [Thread-50:69776] [django.request:152] [base:get_response] [WARNING]- Not Found: /admin/lib/Hui-iconfont/1.0.8/iconfont.css
2017-05-03 14:06:08,220 [Thread-53:69788] [django.request:152] [base:get_response] [WARNING]- Not Found: /admin/welcome.html
2017-05-03 14:06:08,226 [Thread-52:69784] [django.request:152] [base:get_response] [WARNING]- Not Found: /admin/static/h-ui.admin/css/style.css
2017-05-03 14:06:08,369 [Thread-54:69796] [django.request:152] [base:get_response] [WARNING]- Not Found: /admin/lib/jquery/1.9.1/jquery.min.js
2017-05-03 14:06:08,378 [Thread-55:69800] [django.request:152] [base:get_response] [WARNING]- Not Found: /admin/lib/layer/2.4/layer.js
2017-05-03 14:06:08,407 [Thread-56:69804] [django.request:152] [base:get_response] [WARNING]- Not Found: /admin/static/h-ui/js/H-ui.min.js
2017-05-03 14:06:08,437 [Thread-57:69816] [django.request:152] [base:get_response] [WARNING]- Not Found: /admin/static/h-ui.admin/js/H-ui.admin.js
2017-05-03 14:06:08,440 [Thread-58:69820] [django.request:152] [base:get_response] [WARNING]- Not Found: /admin/lib/jquery.contextmenu/jquery.contextmenu.r2.js
2017-05-03 14:06:08,483 [Thread-59:69824] [django.request:152] [base:get_response] [WARNING]- Not Found: /admin/lib/jquery.contextmenu/jquery.contextmenu.r2.js
2017-05-03 14:09:03,490 [Thread-9:70280] [django.request:152] [base:get_response] [WARNING]- Not Found: /admin/static/h-ui/css/H-ui.min.css
2017-05-03 14:09:03,536 [Thread-10:70284] [django.request:152] [base:get_response] [WARNING]- Not Found: /admin/static/h-ui.admin/css/H-ui.admin.css
2017-05-03 14:09:03,546 [Thread-11:68396] [django.request:152] [base:get_response] [WARNING]- Not Found: /admin/lib/Hui-iconfont/1.0.8/iconfont.css
2017-05-03 14:09:03,562 [Thread-13:68616] [django.request:152] [base:get_response] [WARNING]- Not Found: /admin/static/h-ui.admin/css/style.css
2017-05-03 14:09:03,578 [Thread-12:58668] [django.request:152] [base:get_response] [WARNING]- Not Found: /admin/static/h-ui.admin/skin/default/skin.css
2017-05-03 14:09:03,581 [Thread-14:70112] [django.request:152] [base:get_response] [WARNING]- Not Found: /admin/lib/jquery/1.9.1/jquery.min.js
2017-05-03 14:09:03,704 [Thread-15:70292] [django.request:152] [base:get_response] [WARNING]- Not Found: /admin/welcome.html
2017-05-03 14:09:03,753 [Thread-16:69812] [django.request:152] [base:get_response] [WARNING]- Not Found: /admin/lib/layer/2.4/layer.js
2017-05-03 14:09:03,755 [Thread-17:67624] [django.request:152] [base:get_response] [WARNING]- Not Found: /admin/static/h-ui/js/H-ui.min.js
2017-05-03 14:09:03,766 [Thread-18:63528] [django.request:152] [base:get_response] [WARNING]- Not Found: /admin/static/h-ui.admin/js/H-ui.admin.js
2017-05-03 14:09:03,822 [Thread-19:67852] [django.request:152] [base:get_response] [WARNING]- Not Found: /admin/lib/jquery.contextmenu/jquery.contextmenu.r2.js
2017-05-03 14:09:03,848 [Thread-20:69808] [django.request:152] [base:get_response] [WARNING]- Not Found: /admin/static/h-ui/js/H-ui.min.js
2017-05-03 14:09:03,880 [Thread-21:70296] [django.request:152] [base:get_response] [WARNING]- Not Found: /admin/static/h-ui.admin/js/H-ui.admin.js
2017-05-03 14:09:03,915 [Thread-22:70300] [django.request:152] [base:get_response] [WARNING]- Not Found: /admin/lib/jquery.contextmenu/jquery.contextmenu.r2.js
2017-05-03 14:12:26,878 [Thread-30:68684] [django.request:152] [base:get_response] [WARNING]- Not Found: /admin/welcome.html
2017-05-03 14:12:38,052 [Thread-41:68628] [django.request:152] [base:get_response] [WARNING]- Not Found: /admin/article-list.html
2017-05-03 14:12:41,825 [Thread-49:69732] [django.request:152] [base:get_response] [WARNING]- Not Found: /admin/welcome.html
2017-05-03 14:19:50,157 [Thread-19:68692] [django.request:152] [base:get_response] [WARNING]- Not Found: /admin/static/h-ui/css/H-ui.min.css
2017-05-03 14:19:50,160 [Thread-21:53756] [django.request:152] [base:get_response] [WARNING]- Not Found: /admin/lib/Hui-iconfont/1.0.8/iconfont.css
2017-05-03 14:19:50,161 [Thread-20:70180] [django.request:152] [base:get_response] [WARNING]- Not Found: /admin/static/h-ui.admin/css/H-ui.admin.css
2017-05-03 14:19:50,163 [Thread-22:69636] [django.request:152] [base:get_response] [WARNING]- Not Found: /admin/static/h-ui.admin/skin/default/skin.css
2017-05-03 14:19:50,184 [Thread-23:48576] [django.request:152] [base:get_response] [WARNING]- Not Found: /admin/static/h-ui.admin/css/style.css
2017-05-03 14:19:50,223 [Thread-24:67736] [django.request:152] [base:get_response] [WARNING]- Not Found: /admin/lib/jquery/1.9.1/jquery.min.js
2017-05-03 14:19:50,358 [Thread-27:69792] [django.request:152] [base:get_response] [WARNING]- Not Found: /admin/static/h-ui/js/H-ui.min.js
2017-05-03 14:35:13,519 [Thread-58:68320] [django.request:152] [base:get_response] [WARNING]- Not Found: /admin/article-list.html
2017-05-03 20:08:11,910 [Thread-160:71144] [django.request:152] [base:get_response] [WARNING]- Not Found: /admin/member-list.html
2017-05-04 13:08:53,335 [Thread-9:72228] [django.request:124] [exception:handle_uncaught_exception] [ERROR]- Internal Server Error: /admin/projects
Traceback (most recent call last):
  File "D:\python\2.7\setuppath\lib\site-packages\django\core\handlers\exception.py", line 39, in inner
    response = get_response(request)
  File "D:\python\2.7\setuppath\lib\site-packages\django\core\handlers\base.py", line 198, in _get_response
    "returned None instead." % (callback.__module__, view_name)
ValueError: The view apps.views_admin.projects_list didn't return an HttpResponse object. It returned None instead.
2017-05-04 13:34:59,546 [Thread-34:70360] [django.request:152] [base:get_response] [WARNING]- Not Found: /admin/member-add.html
2017-05-04 13:41:01,216 [Thread-8:71780] [django.request:152] [base:get_response] [WARNING]- Not Found: /admin/static/h-ui/css/H-ui.min.css
2017-05-04 13:41:01,217 [Thread-9:67856] [django.request:152] [base:get_response] [WARNING]- Not Found: /admin/static/h-ui.admin/css/H-ui.admin.css
2017-05-04 13:41:01,220 [Thread-11:72304] [django.request:152] [base:get_response] [WARNING]- Not Found: /admin/static/h-ui.admin/skin/default/skin.css
2017-05-04 13:41:01,223 [Thread-10:71924] [django.request:152] [base:get_response] [WARNING]- Not Found: /admin/lib/Hui-iconfont/1.0.8/iconfont.css
2017-05-04 13:41:01,266 [Thread-12:71524] [django.request:152] [base:get_response] [WARNING]- Not Found: /admin/static/h-ui.admin/css/style.css
2017-05-04 13:41:01,269 [Thread-13:72084] [django.request:152] [base:get_response] [WARNING]- Not Found: /admin/lib/jquery/1.9.1/jquery.min.js
2017-05-04 13:41:01,352 [Thread-14:72296] [django.request:152] [base:get_response] [WARNING]- Not Found: /admin/lib/layer/2.4/layer.js
2017-05-04 13:41:01,352 [Thread-15:66984] [django.request:152] [base:get_response] [WARNING]- Not Found: /admin/static/h-ui/js/H-ui.min.js
2017-05-04 13:41:01,357 [Thread-16:67960] [django.request:152] [base:get_response] [WARNING]- Not Found: /admin/static/h-ui.admin/js/H-ui.admin.js
2017-05-04 13:41:01,358 [Thread-17:72336] [django.request:152] [base:get_response] [WARNING]- Not Found: /admin/lib/My97DatePicker/4.8/WdatePicker.js
2017-05-04 13:41:01,391 [Thread-18:72264] [django.request:152] [base:get_response] [WARNING]- Not Found: /admin/lib/jquery.validation/1.14.0/jquery.validate.js
2017-05-04 13:41:01,394 [Thread-19:72676] [django.request:152] [base:get_response] [WARNING]- Not Found: /admin/lib/jquery.validation/1.14.0/validate-methods.js
2017-05-04 13:41:01,424 [Thread-20:71740] [django.request:152] [base:get_response] [WARNING]- Not Found: /admin/lib/jquery.validation/1.14.0/messages_zh.js
2017-05-04 13:41:01,426 [Thread-21:69944] [django.request:152] [base:get_response] [WARNING]- Not Found: /admin/static/h-ui/js/H-ui.min.js
2017-05-04 13:41:01,467 [Thread-22:72232] [django.request:152] [base:get_response] [WARNING]- Not Found: /admin/static/h-ui.admin/js/H-ui.admin.js
2017-05-04 13:41:01,489 [Thread-23:70064] [django.request:152] [base:get_response] [WARNING]- Not Found: /admin/lib/My97DatePicker/4.8/WdatePicker.js
2017-05-04 13:41:01,506 [Thread-24:68684] [django.request:152] [base:get_response] [WARNING]- Not Found: /admin/lib/jquery.validation/1.14.0/jquery.validate.js
2017-05-04 13:41:01,526 [Thread-25:72324] [django.request:152] [base:get_response] [WARNING]- Not Found: /admin/lib/jquery.validation/1.14.0/validate-methods.js
2017-05-04 13:41:01,546 [Thread-26:72472] [django.request:152] [base:get_response] [WARNING]- Not Found: /admin/lib/jquery.validation/1.14.0/messages_zh.js
2017-05-04 13:43:00,977 [Thread-28:69944] [django.request:152] [base:get_response] [WARNING]- Not Found: /admin/lib/My97DatePicker/4.8/WdatePicker.js
2017-05-04 13:43:00,984 [Thread-29:71920] [django.request:152] [base:get_response] [WARNING]- Not Found: /admin/lib/jquery.validation/1.14.0/jquery.validate.js
2017-05-04 13:43:00,986 [Thread-30:70792] [django.request:152] [base:get_response] [WARNING]- Not Found: /admin/lib/jquery.validation/1.14.0/validate-methods.js
2017-05-04 13:43:00,986 [Thread-31:72352] [django.request:152] [base:get_response] [WARNING]- Not Found: /admin/lib/jquery.validation/1.14.0/messages_zh.js
2017-05-04 13:45:29,124 [Thread-35:69656] [django.request:152] [base:get_response] [WARNING]- Not Found: /admin/lib/My97DatePicker/4.8/WdatePicker.js
2017-05-04 13:45:29,145 [Thread-36:66428] [django.request:152] [base:get_response] [WARNING]- Not Found: /admin/lib/jquery.validation/1.14.0/jquery.validate.js
2017-05-04 13:45:29,147 [Thread-37:69800] [django.request:152] [base:get_response] [WARNING]- Not Found: /admin/lib/jquery.validation/1.14.0/validate-methods.js
2017-05-04 13:45:29,153 [Thread-38:72468] [django.request:152] [base:get_response] [WARNING]- Not Found: /admin/lib/jquery.validation/1.14.0/messages_zh.js
2017-05-04 14:03:38,346 [Thread-40:67468] [django.request:152] [base:get_response] [WARNING]- Not Found: /admin/lib/My97DatePicker/4.8/WdatePicker.js
2017-05-04 14:03:38,358 [Thread-41:71564] [django.request:152] [base:get_response] [WARNING]- Not Found: /admin/lib/jquery.validation/1.14.0/jquery.validate.js
2017-05-04 14:03:38,361 [Thread-42:71140] [django.request:152] [base:get_response] [WARNING]- Not Found: /admin/lib/jquery.validation/1.14.0/validate-methods.js
2017-05-04 14:03:38,362 [Thread-43:71004] [django.request:152] [base:get_response] [WARNING]- Not Found: /admin/lib/jquery.validation/1.14.0/messages_zh.js
2017-05-04 14:03:38,397 [Thread-44:72236] [django.request:152] [base:get_response] [WARNING]- Not Found: /admin/lib/jquery.validation/1.14.0/messages_zh.js
2017-05-04 14:12:25,694 [Thread-46:68736] [django.request:152] [base:get_response] [WARNING]- Not Found: /admin/lib/My97DatePicker/4.8/WdatePicker.js
2017-05-04 14:12:25,716 [Thread-47:72304] [django.request:152] [base:get_response] [WARNING]- Not Found: /admin/lib/jquery.validation/1.14.0/jquery.validate.js
2017-05-04 14:12:25,717 [Thread-48:70064] [django.request:152] [base:get_response] [WARNING]- Not Found: /admin/lib/jquery.validation/1.14.0/messages_zh.js
2017-05-04 14:12:25,720 [Thread-49:72228] [django.request:152] [base:get_response] [WARNING]- Not Found: /admin/lib/jquery.validation/1.14.0/validate-methods.js
2017-05-04 14:12:25,752 [Thread-50:71904] [django.request:152] [base:get_response] [WARNING]- Not Found: /admin/lib/jquery.validation/1.14.0/messages_zh.js
2017-05-04 18:15:18,009 [Thread-52:71656] [django.request:152] [base:get_response] [WARNING]- Not Found: /admin/lib/My97DatePicker/4.8/WdatePicker.js
2017-05-04 18:15:18,030 [Thread-53:71184] [django.request:152] [base:get_response] [WARNING]- Not Found: /admin/lib/jquery.validation/1.14.0/jquery.validate.js
2017-05-04 18:15:18,032 [Thread-54:72440] [django.request:152] [base:get_response] [WARNING]- Not Found: /admin/lib/jquery.validation/1.14.0/validate-methods.js
2017-05-04 18:15:18,033 [Thread-55:73308] [django.request:152] [base:get_response] [WARNING]- Not Found: /admin/lib/jquery.validation/1.14.0/messages_zh.js
2017-05-04 18:15:18,165 [Thread-56:68736] [django.request:152] [base:get_response] [WARNING]- Not Found: /admin/lib/My97DatePicker/4.8/WdatePicker.js
2017-05-04 18:15:18,216 [Thread-57:68648] [django.request:152] [base:get_response] [WARNING]- Not Found: /admin/lib/jquery.validation/1.14.0/jquery.validate.js
2017-05-04 18:15:18,256 [Thread-58:72020] [django.request:152] [base:get_response] [WARNING]- Not Found: /admin/lib/jquery.validation/1.14.0/validate-methods.js
2017-05-04 18:15:18,280 [Thread-59:73544] [django.request:152] [base:get_response] [WARNING]- Not Found: /admin/lib/jquery.validation/1.14.0/messages_zh.js
2017-05-04 18:15:46,295 [Thread-64:74116] [django.request:152] [base:get_response] [WARNING]- Not Found: /admin/lib/My97DatePicker/4.8/WdatePicker.js
2017-05-04 18:15:46,326 [Thread-65:73616] [django.request:152] [base:get_response] [WARNING]- Not Found: /admin/lib/jquery.validation/1.14.0/jquery.validate.js
2017-05-04 18:15:46,331 [Thread-66:74284] [django.request:152] [base:get_response] [WARNING]- Not Found: /admin/lib/jquery.validation/1.14.0/validate-methods.js
2017-05-04 18:15:46,332 [Thread-67:69160] [django.request:152] [base:get_response] [WARNING]- Not Found: /admin/lib/jquery.validation/1.14.0/messages_zh.js
2017-05-04 18:16:29,734 [Thread-70:62572] [django.request:152] [base:get_response] [WARNING]- Not Found: /admin/lib/jquery.validation/1.14.0/jquery.validate.js
2017-05-04 18:16:29,740 [Thread-72:74204] [django.request:152] [base:get_response] [WARNING]- Not Found: /admin/lib/jquery.validation/1.14.0/validate-methods.js
2017-05-04 18:16:29,740 [Thread-71:74568] [django.request:152] [base:get_response] [WARNING]- Not Found: /admin/lib/My97DatePicker/4.8/WdatePicker.js
2017-05-04 18:16:29,742 [Thread-73:74188] [django.request:152] [base:get_response] [WARNING]- Not Found: /admin/lib/jquery.validation/1.14.0/messages_zh.js
2017-05-04 18:16:29,769 [Thread-74:69192] [django.request:152] [base:get_response] [WARNING]- Not Found: /admin/lib/jquery.validation/1.14.0/jquery.validate.js
2017-05-04 18:16:29,799 [Thread-75:72164] [django.request:152] [base:get_response] [WARNING]- Not Found: /admin/lib/jquery.validation/1.14.0/validate-methods.js
2017-05-04 18:16:29,823 [Thread-76:74712] [django.request:152] [base:get_response] [WARNING]- Not Found: /admin/lib/jquery.validation/1.14.0/messages_zh.js
2017-05-04 18:16:56,111 [Thread-79:74308] [django.request:152] [base:get_response] [WARNING]- Not Found: /admin/lib/My97DatePicker/4.8/WdatePicker.js
2017-05-04 18:16:56,115 [Thread-80:69160] [django.request:152] [base:get_response] [WARNING]- Not Found: /admin/lib/jquery.validation/1.14.0/jquery.validate.js
2017-05-04 18:16:56,119 [Thread-81:74212] [django.request:152] [base:get_response] [WARNING]- Not Found: /admin/lib/jquery.validation/1.14.0/validate-methods.js
2017-05-04 18:16:56,121 [Thread-82:73864] [django.request:152] [base:get_response] [WARNING]- Not Found: /admin/lib/jquery.validation/1.14.0/messages_zh.js
2017-05-04 18:16:56,174 [Thread-83:73612] [django.request:152] [base:get_response] [WARNING]- Not Found: /admin/lib/jquery.validation/1.14.0/messages_zh.js
2017-05-04 18:17:04,821 [Thread-85:74060] [django.request:152] [base:get_response] [WARNING]- Not Found: /admin/lib/My97DatePicker/4.8/WdatePicker.js
2017-05-04 18:17:04,822 [Thread-86:74688] [django.request:152] [base:get_response] [WARNING]- Not Found: /admin/lib/jquery.validation/1.14.0/jquery.validate.js
2017-05-04 18:17:04,828 [Thread-87:67968] [django.request:152] [base:get_response] [WARNING]- Not Found: /admin/lib/jquery.validation/1.14.0/validate-methods.js
2017-05-04 18:17:04,832 [Thread-88:74224] [django.request:152] [base:get_response] [WARNING]- Not Found: /admin/lib/jquery.validation/1.14.0/messages_zh.js
2017-05-04 19:19:45,914 [Thread-7:77700] [django.request:124] [exception:handle_uncaught_exception] [ERROR]- Internal Server Error: /admin/projects
Traceback (most recent call last):
  File "D:\python\2.7\setuppath\lib\site-packages\django\core\handlers\exception.py", line 39, in inner
    response = get_response(request)
  File "D:\python\2.7\setuppath\lib\site-packages\django\core\handlers\base.py", line 187, in _get_response
    response = self.process_exception_by_middleware(e, request)
  File "D:\python\2.7\setuppath\lib\site-packages\django\core\handlers\base.py", line 185, in _get_response
    response = wrapped_callback(request, *callback_args, **callback_kwargs)
  File "E:/my/projects/python/git_web_hooks\apps\views_admin.py", line 42, in projects_list
    my_projects_mod = ProjectsModel()
  File "E:/my/projects/python/git_web_hooks\apps\models\ProjectsModel.py", line 10, in __init__
    MySQL.__init__()
TypeError: unbound method __init__() must be called with MySQL instance as first argument (got nothing instead)
2017-05-04 19:20:32,490 [Thread-9:74352] [django.request:152] [base:get_response] [WARNING]- Not Found: /admin/lib/My97DatePicker/4.8/WdatePicker.js
2017-05-04 19:20:32,529 [Thread-10:74196] [django.request:152] [base:get_response] [WARNING]- Not Found: /admin/lib/jquery.validation/1.14.0/jquery.validate.js
2017-05-04 19:20:32,532 [Thread-11:76872] [django.request:152] [base:get_response] [WARNING]- Not Found: /admin/lib/jquery.validation/1.14.0/validate-methods.js
2017-05-04 19:20:32,535 [Thread-12:76876] [django.request:152] [base:get_response] [WARNING]- Not Found: /admin/lib/jquery.validation/1.14.0/messages_zh.js
2017-05-04 19:20:32,581 [Thread-13:75836] [django.request:152] [base:get_response] [WARNING]- Not Found: /admin/lib/jquery.validation/1.14.0/messages_zh.js
2017-05-04 19:20:39,750 [Thread-15:76412] [django.request:152] [base:get_response] [WARNING]- Not Found: /admin/lib/My97DatePicker/4.8/WdatePicker.js
2017-05-04 19:20:39,763 [Thread-16:69868] [django.request:152] [base:get_response] [WARNING]- Not Found: /admin/lib/jquery.validation/1.14.0/jquery.validate.js
2017-05-04 19:20:39,766 [Thread-17:77060] [django.request:152] [base:get_response] [WARNING]- Not Found: /admin/lib/jquery.validation/1.14.0/validate-methods.js
2017-05-04 19:20:39,772 [Thread-18:77752] [django.request:152] [base:get_response] [WARNING]- Not Found: /admin/lib/jquery.validation/1.14.0/messages_zh.js
2017-05-04 19:21:06,596 [Thread-19:74940] [django.request:152] [base:get_response] [WARNING]- Not Found: /admin/project_action
2017-05-04 19:21:41,563 [Thread-37:77180] [django.request:152] [base:get_response] [WARNING]- Not Found: /admin/lib/My97DatePicker/4.8/WdatePicker.js
2017-05-04 19:21:41,569 [Thread-38:76092] [django.request:152] [base:get_response] [WARNING]- Not Found: /admin/lib/jquery.validation/1.14.0/jquery.validate.js
2017-05-04 19:21:41,575 [Thread-39:76836] [django.request:152] [base:get_response] [WARNING]- Not Found: /admin/lib/jquery.validation/1.14.0/validate-methods.js
2017-05-04 19:21:41,575 [Thread-40:76848] [django.request:152] [base:get_response] [WARNING]- Not Found: /admin/lib/jquery.validation/1.14.0/messages_zh.js
2017-05-04 19:21:51,354 [Thread-43:76176] [django.request:152] [base:get_response] [WARNING]- Not Found: /admin/lib/My97DatePicker/4.8/WdatePicker.js
2017-05-04 19:21:51,371 [Thread-44:76916] [django.request:152] [base:get_response] [WARNING]- Not Found: /admin/lib/jquery.validation/1.14.0/validate-methods.js
2017-05-04 19:21:51,378 [Thread-45:77772] [django.request:152] [base:get_response] [WARNING]- Not Found: /admin/lib/jquery.validation/1.14.0/jquery.validate.js
2017-05-04 19:21:51,381 [Thread-46:77712] [django.request:152] [base:get_response] [WARNING]- Not Found: /admin/lib/jquery.validation/1.14.0/messages_zh.js
2017-05-04 19:21:51,413 [Thread-47:76904] [django.request:152] [base:get_response] [WARNING]- Not Found: /admin/lib/jquery.validation/1.14.0/validate-methods.js
2017-05-04 19:21:51,444 [Thread-48:76088] [django.request:152] [base:get_response] [WARNING]- Not Found: /admin/lib/jquery.validation/1.14.0/messages_zh.js
2017-05-04 19:22:10,325 [Thread-49:77172] [django.request:124] [exception:handle_uncaught_exception] [ERROR]- Internal Server Error: /admin/project.action
Traceback (most recent call last):
  File "D:\python\2.7\setuppath\lib\site-packages\django\core\handlers\exception.py", line 39, in inner
    response = get_response(request)
  File "D:\python\2.7\setuppath\lib\site-packages\django\core\handlers\base.py", line 187, in _get_response
    response = self.process_exception_by_middleware(e, request)
  File "D:\python\2.7\setuppath\lib\site-packages\django\core\handlers\base.py", line 185, in _get_response
    response = wrapped_callback(request, *callback_args, **callback_kwargs)
  File "E:/my/projects/python/git_web_hooks\apps\views_admin.py", line 63, in project_action
    del params['id']
  File "D:\python\2.7\setuppath\lib\site-packages\django\http\request.py", line 427, in __delitem__
    self._assert_mutable()
  File "D:\python\2.7\setuppath\lib\site-packages\django\http\request.py", line 418, in _assert_mutable
    raise AttributeError("This QueryDict instance is immutable")
AttributeError: This QueryDict instance is immutable
2017-05-04 19:22:23,632 [Thread-62:77456] [django.request:152] [base:get_response] [WARNING]- Not Found: /admin/lib/My97DatePicker/4.8/WdatePicker.js
2017-05-04 19:22:23,680 [Thread-63:76464] [django.request:152] [base:get_response] [WARNING]- Not Found: /admin/lib/jquery.validation/1.14.0/jquery.validate.js
2017-05-04 19:22:23,766 [Thread-64:74152] [django.request:152] [base:get_response] [WARNING]- Not Found: /admin/lib/jquery.validation/1.14.0/validate-methods.js
2017-05-04 19:22:23,770 [Thread-65:30404] [django.request:152] [base:get_response] [WARNING]- Not Found: /admin/lib/jquery.validation/1.14.0/messages_zh.js
2017-05-04 19:22:23,868 [Thread-67:77720] [django.request:152] [base:get_response] [WARNING]- Not Found: /admin/lib/My97DatePicker/4.8/WdatePicker.js
2017-05-04 19:22:23,934 [Thread-68:76820] [django.request:152] [base:get_response] [WARNING]- Not Found: /admin/lib/jquery.validation/1.14.0/jquery.validate.js
2017-05-04 19:22:23,990 [Thread-69:76256] [django.request:152] [base:get_response] [WARNING]- Not Found: /admin/lib/jquery.validation/1.14.0/validate-methods.js
2017-05-04 19:22:24,039 [Thread-70:76956] [django.request:152] [base:get_response] [WARNING]- Not Found: /admin/lib/jquery.validation/1.14.0/messages_zh.js
2017-05-04 19:23:12,339 [Thread-72:77244] [django.request:124] [exception:handle_uncaught_exception] [ERROR]- Internal Server Error: /admin/project.action
Traceback (most recent call last):
  File "D:\python\2.7\setuppath\lib\site-packages\django\core\handlers\exception.py", line 39, in inner
    response = get_response(request)
  File "D:\python\2.7\setuppath\lib\site-packages\django\core\handlers\base.py", line 187, in _get_response
    response = self.process_exception_by_middleware(e, request)
  File "D:\python\2.7\setuppath\lib\site-packages\django\core\handlers\base.py", line 185, in _get_response
    response = wrapped_callback(request, *callback_args, **callback_kwargs)
  File "E:/my/projects/python/git_web_hooks\apps\views_admin.py", line 63, in project_action
    del params['id']
  File "D:\python\2.7\setuppath\lib\site-packages\django\http\request.py", line 427, in __delitem__
    self._assert_mutable()
  File "D:\python\2.7\setuppath\lib\site-packages\django\http\request.py", line 418, in _assert_mutable
    raise AttributeError("This QueryDict instance is immutable")
AttributeError: This QueryDict instance is immutable
2017-05-05 14:34:52,470 [Thread-13:77176] [django.request:152] [base:get_response] [WARNING]- Not Found: /admin/lib/jquery.validation/1.14.0/validate-methods.js
2017-05-05 14:34:52,470 [Thread-14:78224] [django.request:152] [base:get_response] [WARNING]- Not Found: /admin/lib/jquery.validation/1.14.0/messages_zh.js
2017-05-05 14:34:52,470 [Thread-12:73652] [django.request:152] [base:get_response] [WARNING]- Not Found: /admin/lib/jquery.validation/1.14.0/jquery.validate.js
2017-05-05 14:34:52,471 [Thread-11:79136] [django.request:152] [base:get_response] [WARNING]- Not Found: /admin/lib/My97DatePicker/4.8/WdatePicker.js
2017-05-05 14:34:58,177 [Thread-18:76840] [django.request:152] [base:get_response] [WARNING]- Not Found: /admin/lib/My97DatePicker/4.8/WdatePicker.js
2017-05-05 14:34:58,180 [Thread-21:78188] [django.request:152] [base:get_response] [WARNING]- Not Found: /admin/lib/jquery.validation/1.14.0/messages_zh.js
2017-05-05 14:34:58,180 [Thread-19:77640] [django.request:152] [base:get_response] [WARNING]- Not Found: /admin/lib/jquery.validation/1.14.0/jquery.validate.js
2017-05-05 14:34:58,180 [Thread-20:76460] [django.request:152] [base:get_response] [WARNING]- Not Found: /admin/lib/jquery.validation/1.14.0/validate-methods.js
2017-05-05 14:35:51,884 [Thread-26:79192] [django.request:152] [base:get_response] [WARNING]- Not Found: /admin/lib/My97DatePicker/4.8/WdatePicker.js
2017-05-05 14:35:51,885 [Thread-27:79220] [django.request:152] [base:get_response] [WARNING]- Not Found: /admin/lib/jquery.validation/1.14.0/jquery.validate.js
2017-05-05 14:35:51,887 [Thread-28:69284] [django.request:152] [base:get_response] [WARNING]- Not Found: /admin/lib/jquery.validation/1.14.0/validate-methods.js
2017-05-05 14:35:51,888 [Thread-29:79308] [django.request:152] [base:get_response] [WARNING]- Not Found: /admin/lib/jquery.validation/1.14.0/messages_zh.js
2017-05-05 14:35:51,928 [Thread-30:64240] [django.request:152] [base:get_response] [WARNING]- Not Found: /admin/lib/jquery.validation/1.14.0/jquery.validate.js
2017-05-05 14:35:51,951 [Thread-31:79604] [django.request:152] [base:get_response] [WARNING]- Not Found: /admin/lib/jquery.validation/1.14.0/validate-methods.js
2017-05-05 14:35:51,971 [Thread-32:79104] [django.request:152] [base:get_response] [WARNING]- Not Found: /admin/lib/jquery.validation/1.14.0/messages_zh.js
2017-05-05 20:05:05,565 [Thread-14:80300] [django.request:152] [base:get_response] [WARNING]- Not Found: /admin/lib/My97DatePicker/4.8/WdatePicker.js
2017-05-05 20:05:05,565 [Thread-15:78216] [django.request:152] [base:get_response] [WARNING]- Not Found: /admin/lib/jquery.validation/1.14.0/jquery.validate.js
2017-05-05 20:05:05,565 [Thread-17:79012] [django.request:152] [base:get_response] [WARNING]- Not Found: /admin/lib/jquery.validation/1.14.0/messages_zh.js
2017-05-05 20:05:05,565 [Thread-16:80088] [django.request:152] [base:get_response] [WARNING]- Not Found: /admin/lib/jquery.validation/1.14.0/validate-methods.js
2017-05-05 20:05:05,598 [Thread-18:75832] [django.request:152] [base:get_response] [WARNING]- Not Found: /admin/lib/jquery.validation/1.14.0/jquery.validate.js
2017-05-05 20:05:05,615 [Thread-19:63880] [django.request:152] [base:get_response] [WARNING]- Not Found: /admin/lib/jquery.validation/1.14.0/validate-methods.js
2017-05-05 20:05:05,632 [Thread-20:80736] [django.request:152] [base:get_response] [WARNING]- Not Found: /admin/lib/jquery.validation/1.14.0/messages_zh.js
2017-05-05 20:05:17,421 [Thread-22:80740] [django.request:152] [base:get_response] [WARNING]- Not Found: /admin/lib/My97DatePicker/4.8/WdatePicker.js
2017-05-05 20:05:17,426 [Thread-23:80880] [django.request:152] [base:get_response] [WARNING]- Not Found: /admin/lib/jquery.validation/1.14.0/jquery.validate.js
2017-05-05 20:05:17,430 [Thread-24:74188] [django.request:152] [base:get_response] [WARNING]- Not Found: /admin/lib/jquery.validation/1.14.0/validate-methods.js
2017-05-05 20:05:17,430 [Thread-25:79016] [django.request:152] [base:get_response] [WARNING]- Not Found: /admin/lib/jquery.validation/1.14.0/messages_zh.js
2017-05-05 20:05:17,460 [Thread-26:80768] [django.request:152] [base:get_response] [WARNING]- Not Found: /admin/lib/jquery.validation/1.14.0/messages_zh.js
2017-05-06 12:40:26,099 [Thread-29:84296] [django.request:152] [base:get_response] [WARNING]- Not Found: /admin/lib/My97DatePicker/4.8/WdatePicker.js
2017-05-06 12:40:26,102 [Thread-30:84820] [django.request:152] [base:get_response] [WARNING]- Not Found: /admin/lib/jquery.validation/1.14.0/validate-methods.js
2017-05-06 12:40:26,105 [Thread-31:84708] [django.request:152] [base:get_response] [WARNING]- Not Found: /admin/lib/jquery.validation/1.14.0/jquery.validate.js
2017-05-06 12:40:26,108 [Thread-32:84036] [django.request:152] [base:get_response] [WARNING]- Not Found: /admin/lib/jquery.validation/1.14.0/messages_zh.js
2017-05-06 12:40:26,144 [Thread-33:84104] [django.request:152] [base:get_response] [WARNING]- Not Found: /admin/lib/jquery.validation/1.14.0/validate-methods.js
2017-05-06 12:40:26,171 [Thread-34:84808] [django.request:152] [base:get_response] [WARNING]- Not Found: /admin/lib/jquery.validation/1.14.0/messages_zh.js
2017-05-06 12:43:39,799 [Thread-8:83456] [django.request:152] [base:get_response] [WARNING]- Not Found: /admin/lib/jquery.validation/1.14.0/jquery.validate.js
2017-05-06 12:43:39,799 [Thread-7:84220] [django.request:152] [base:get_response] [WARNING]- Not Found: /admin/lib/My97DatePicker/4.8/WdatePicker.js
2017-05-06 12:43:39,799 [Thread-9:82972] [django.request:152] [base:get_response] [WARNING]- Not Found: /admin/lib/jquery.validation/1.14.0/messages_zh.js
2017-05-06 13:19:09,410 [Thread-7:83184] [django.request:124] [exception:handle_uncaught_exception] [ERROR]- Internal Server Error: /admin/projects
Traceback (most recent call last):
  File "D:\python\2.7\setuppath\lib\site-packages\django\core\handlers\exception.py", line 39, in inner
    response = get_response(request)
  File "D:\python\2.7\setuppath\lib\site-packages\django\core\handlers\base.py", line 187, in _get_response
    response = self.process_exception_by_middleware(e, request)
  File "D:\python\2.7\setuppath\lib\site-packages\django\core\handlers\base.py", line 185, in _get_response
    response = wrapped_callback(request, *callback_args, **callback_kwargs)
  File "E:/my/projects/python/git_web_hooks\apps\views_admin.py", line 51, in projects_list
    return render(request, 'projects.html', lists)
  File "D:\python\2.7\setuppath\lib\site-packages\django\shortcuts.py", line 30, in render
    content = loader.render_to_string(template_name, context, request, using=using)
  File "D:\python\2.7\setuppath\lib\site-packages\django\template\loader.py", line 68, in render_to_string
    return template.render(context, request)
  File "D:\python\2.7\setuppath\lib\site-packages\django\template\backends\django.py", line 64, in render
    context = make_context(context, request, autoescape=self.backend.engine.autoescape)
  File "D:\python\2.7\setuppath\lib\site-packages\django\template\context.py", line 267, in make_context
    context.push(original_context)
  File "D:\python\2.7\setuppath\lib\site-packages\django\template\context.py", line 59, in push
    return ContextDict(self, *dicts, **kwargs)
  File "D:\python\2.7\setuppath\lib\site-packages\django\template\context.py", line 18, in __init__
    super(ContextDict, self).__init__(*args, **kwargs)
ValueError: dictionary update sequence element #0 has length 14; 2 is required
2017-05-06 13:19:33,746 [Thread-8:71232] [django.request:124] [exception:handle_uncaught_exception] [ERROR]- Internal Server Error: /admin/projects
Traceback (most recent call last):
  File "D:\python\2.7\setuppath\lib\site-packages\django\core\handlers\exception.py", line 39, in inner
    response = get_response(request)
  File "D:\python\2.7\setuppath\lib\site-packages\django\core\handlers\base.py", line 187, in _get_response
    response = self.process_exception_by_middleware(e, request)
  File "D:\python\2.7\setuppath\lib\site-packages\django\core\handlers\base.py", line 185, in _get_response
    response = wrapped_callback(request, *callback_args, **callback_kwargs)
  File "E:/my/projects/python/git_web_hooks\apps\views_admin.py", line 51, in projects_list
    return render(request, 'projects.html', lists)
  File "D:\python\2.7\setuppath\lib\site-packages\django\shortcuts.py", line 30, in render
    content = loader.render_to_string(template_name, context, request, using=using)
  File "D:\python\2.7\setuppath\lib\site-packages\django\template\loader.py", line 68, in render_to_string
    return template.render(context, request)
  File "D:\python\2.7\setuppath\lib\site-packages\django\template\backends\django.py", line 64, in render
    context = make_context(context, request, autoescape=self.backend.engine.autoescape)
  File "D:\python\2.7\setuppath\lib\site-packages\django\template\context.py", line 267, in make_context
    context.push(original_context)
  File "D:\python\2.7\setuppath\lib\site-packages\django\template\context.py", line 59, in push
    return ContextDict(self, *dicts, **kwargs)
  File "D:\python\2.7\setuppath\lib\site-packages\django\template\context.py", line 18, in __init__
    super(ContextDict, self).__init__(*args, **kwargs)
ValueError: dictionary update sequence element #0 has length 14; 2 is required
2017-05-06 13:25:50,469 [Thread-10:82260] [django.request:124] [exception:handle_uncaught_exception] [ERROR]- Internal Server Error: /admin/projects
Traceback (most recent call last):
  File "D:\python\2.7\setuppath\lib\site-packages\django\core\handlers\exception.py", line 39, in inner
    response = get_response(request)
  File "D:\python\2.7\setuppath\lib\site-packages\django\core\handlers\base.py", line 187, in _get_response
    response = self.process_exception_by_middleware(e, request)
  File "D:\python\2.7\setuppath\lib\site-packages\django\core\handlers\base.py", line 185, in _get_response
    response = wrapped_callback(request, *callback_args, **callback_kwargs)
  File "E:/my/projects/python/git_web_hooks\apps\views_admin.py", line 51, in projects_list
    return render(request, 'projects.html', lists)
  File "D:\python\2.7\setuppath\lib\site-packages\django\shortcuts.py", line 30, in render
    content = loader.render_to_string(template_name, context, request, using=using)
  File "D:\python\2.7\setuppath\lib\site-packages\django\template\loader.py", line 67, in render_to_string
    template = get_template(template_name, using=using)
  File "D:\python\2.7\setuppath\lib\site-packages\django\template\loader.py", line 21, in get_template
    return engine.get_template(template_name)
  File "D:\python\2.7\setuppath\lib\site-packages\django\template\backends\django.py", line 39, in get_template
    return Template(self.engine.get_template(template_name), self)
  File "D:\python\2.7\setuppath\lib\site-packages\django\template\engine.py", line 160, in get_template
    template, origin = self.find_template(template_name)
  File "D:\python\2.7\setuppath\lib\site-packages\django\template\engine.py", line 134, in find_template
    name, template_dirs=dirs, skip=skip,
  File "D:\python\2.7\setuppath\lib\site-packages\django\template\loaders\base.py", line 44, in get_template
    contents, origin, origin.template_name, self.engine,
  File "D:\python\2.7\setuppath\lib\site-packages\django\template\base.py", line 191, in __init__
    self.nodelist = self.compile_nodelist()
  File "D:\python\2.7\setuppath\lib\site-packages\django\template\base.py", line 233, in compile_nodelist
    return parser.parse()
  File "D:\python\2.7\setuppath\lib\site-packages\django\template\base.py", line 518, in parse
    raise self.error(token, e)
TemplateSyntaxError: Invalid block tag on line 60: 'endblock', expected 'empty' or 'endfor'. Did you forget to register or load this tag?
2017-05-06 13:25:54,861 [Thread-9:83692] [django.request:124] [exception:handle_uncaught_exception] [ERROR]- Internal Server Error: /admin/projects
Traceback (most recent call last):
  File "D:\python\2.7\setuppath\lib\site-packages\django\core\handlers\exception.py", line 39, in inner
    response = get_response(request)
  File "D:\python\2.7\setuppath\lib\site-packages\django\core\handlers\base.py", line 187, in _get_response
    response = self.process_exception_by_middleware(e, request)
  File "D:\python\2.7\setuppath\lib\site-packages\django\core\handlers\base.py", line 185, in _get_response
    response = wrapped_callback(request, *callback_args, **callback_kwargs)
  File "E:/my/projects/python/git_web_hooks\apps\views_admin.py", line 51, in projects_list
    return render(request, 'projects.html', lists)
  File "D:\python\2.7\setuppath\lib\site-packages\django\shortcuts.py", line 30, in render
    content = loader.render_to_string(template_name, context, request, using=using)
  File "D:\python\2.7\setuppath\lib\site-packages\django\template\loader.py", line 67, in render_to_string
    template = get_template(template_name, using=using)
  File "D:\python\2.7\setuppath\lib\site-packages\django\template\loader.py", line 21, in get_template
    return engine.get_template(template_name)
  File "D:\python\2.7\setuppath\lib\site-packages\django\template\backends\django.py", line 39, in get_template
    return Template(self.engine.get_template(template_name), self)
  File "D:\python\2.7\setuppath\lib\site-packages\django\template\engine.py", line 160, in get_template
    template, origin = self.find_template(template_name)
  File "D:\python\2.7\setuppath\lib\site-packages\django\template\engine.py", line 134, in find_template
    name, template_dirs=dirs, skip=skip,
  File "D:\python\2.7\setuppath\lib\site-packages\django\template\loaders\base.py", line 44, in get_template
    contents, origin, origin.template_name, self.engine,
  File "D:\python\2.7\setuppath\lib\site-packages\django\template\base.py", line 191, in __init__
    self.nodelist = self.compile_nodelist()
  File "D:\python\2.7\setuppath\lib\site-packages\django\template\base.py", line 233, in compile_nodelist
    return parser.parse()
  File "D:\python\2.7\setuppath\lib\site-packages\django\template\base.py", line 518, in parse
    raise self.error(token, e)
TemplateSyntaxError: Invalid block tag on line 60: 'endblock', expected 'empty' or 'endfor'. Did you forget to register or load this tag?
2017-05-06 13:27:01,927 [Thread-13:83044] [django.request:124] [exception:handle_uncaught_exception] [ERROR]- Internal Server Error: /admin/projects
Traceback (most recent call last):
  File "D:\python\2.7\setuppath\lib\site-packages\django\core\handlers\exception.py", line 39, in inner
    response = get_response(request)
  File "D:\python\2.7\setuppath\lib\site-packages\django\core\handlers\base.py", line 187, in _get_response
    response = self.process_exception_by_middleware(e, request)
  File "D:\python\2.7\setuppath\lib\site-packages\django\core\handlers\base.py", line 185, in _get_response
    response = wrapped_callback(request, *callback_args, **callback_kwargs)
  File "E:/my/projects/python/git_web_hooks\apps\views_admin.py", line 51, in projects_list
    return render(request, 'projects.html', lists)
  File "D:\python\2.7\setuppath\lib\site-packages\django\shortcuts.py", line 30, in render
    content = loader.render_to_string(template_name, context, request, using=using)
  File "D:\python\2.7\setuppath\lib\site-packages\django\template\loader.py", line 68, in render_to_string
    return template.render(context, request)
  File "D:\python\2.7\setuppath\lib\site-packages\django\template\backends\django.py", line 64, in render
    context = make_context(context, request, autoescape=self.backend.engine.autoescape)
  File "D:\python\2.7\setuppath\lib\site-packages\django\template\context.py", line 267, in make_context
    context.push(original_context)
  File "D:\python\2.7\setuppath\lib\site-packages\django\template\context.py", line 59, in push
    return ContextDict(self, *dicts, **kwargs)
  File "D:\python\2.7\setuppath\lib\site-packages\django\template\context.py", line 18, in __init__
    super(ContextDict, self).__init__(*args, **kwargs)
ValueError: dictionary update sequence element #0 has length 14; 2 is required
2017-05-06 13:29:56,081 [Thread-12:84852] [django.request:152] [base:get_response] [WARNING]- Not Found: /admin/lib/jquery.validation/1.14.0/jquery.validate.js
2017-05-06 13:29:56,092 [Thread-13:85464] [django.request:152] [base:get_response] [WARNING]- Not Found: /admin/lib/My97DatePicker/4.8/WdatePicker.js
2017-05-06 13:29:56,095 [Thread-15:85596] [django.request:152] [base:get_response] [WARNING]- Not Found: /admin/lib/jquery.validation/1.14.0/validate-methods.js
2017-05-06 13:29:56,098 [Thread-14:82260] [django.request:152] [base:get_response] [WARNING]- Not Found: /admin/lib/jquery.validation/1.14.0/messages_zh.js
2017-05-06 13:29:56,141 [Thread-16:84056] [django.request:152] [base:get_response] [WARNING]- Not Found: /admin/lib/jquery.validation/1.14.0/jquery.validate.js
2017-05-06 13:29:56,187 [Thread-17:85684] [django.request:152] [base:get_response] [WARNING]- Not Found: /admin/lib/jquery.validation/1.14.0/validate-methods.js
2017-05-06 13:29:56,213 [Thread-18:83552] [django.request:152] [base:get_response] [WARNING]- Not Found: /admin/lib/jquery.validation/1.14.0/messages_zh.js
2017-05-06 13:30:44,012 [Thread-8:86256] [django.request:152] [base:get_response] [WARNING]- Not Found: /admin/lib/jquery.validation/1.14.0/messages_zh.js
2017-05-06 13:30:44,017 [Thread-9:86260] [django.request:152] [base:get_response] [WARNING]- Not Found: /admin/lib/My97DatePicker/4.8/WdatePicker.js
2017-05-06 13:30:44,029 [Thread-10:86264] [django.request:152] [base:get_response] [WARNING]- Not Found: /admin/lib/jquery.validation/1.14.0/jquery.validate.js
2017-05-06 13:30:44,039 [Thread-11:86268] [django.request:152] [base:get_response] [WARNING]- Not Found: /admin/lib/jquery.validation/1.14.0/validate-methods.js
2017-05-06 13:30:44,095 [Thread-12:86272] [django.request:152] [base:get_response] [WARNING]- Not Found: /admin/lib/jquery.validation/1.14.0/messages_zh.js
2017-05-06 13:30:58,674 [Thread-15:86360] [django.request:152] [base:get_response] [WARNING]- Not Found: /admin/lib/jquery.validation/1.14.0/messages_zh.js
2017-05-06 13:30:58,674 [Thread-14:86356] [django.request:152] [base:get_response] [WARNING]- Not Found: /admin/lib/jquery.validation/1.14.0/validate-methods.js
2017-05-06 13:30:58,680 [Thread-16:86364] [django.request:152] [base:get_response] [WARNING]- Not Found: /admin/lib/My97DatePicker/4.8/WdatePicker.js
2017-05-06 13:30:58,683 [Thread-17:86368] [django.request:152] [base:get_response] [WARNING]- Not Found: /admin/lib/jquery.validation/1.14.0/jquery.validate.js
2017-05-06 13:30:58,711 [Thread-18:86372] [django.request:152] [base:get_response] [WARNING]- Not Found: /admin/lib/jquery.validation/1.14.0/validate-methods.js
2017-05-06 13:30:58,736 [Thread-19:86376] [django.request:152] [base:get_response] [WARNING]- Not Found: /admin/lib/jquery.validation/1.14.0/messages_zh.js
2017-05-06 13:31:38,312 [Thread-22:86472] [django.request:152] [base:get_response] [WARNING]- Not Found: /admin/lib/My97DatePicker/4.8/WdatePicker.js
2017-05-06 13:31:38,315 [Thread-23:86476] [django.request:152] [base:get_response] [WARNING]- Not Found: /admin/lib/jquery.validation/1.14.0/jquery.validate.js
2017-05-06 13:31:38,318 [Thread-24:86480] [django.request:152] [base:get_response] [WARNING]- Not Found: /admin/lib/jquery.validation/1.14.0/validate-methods.js
2017-05-06 13:31:38,319 [Thread-25:86484] [django.request:152] [base:get_response] [WARNING]- Not Found: /admin/lib/jquery.validation/1.14.0/messages_zh.js
2017-05-06 13:34:16,486 [Thread-9:86112] [django.request:152] [base:get_response] [WARNING]- Not Found: /admin/lib/My97DatePicker/4.8/WdatePicker.js
2017-05-06 13:34:16,490 [Thread-10:85680] [django.request:152] [base:get_response] [WARNING]- Not Found: /admin/lib/jquery.validation/1.14.0/validate-methods.js
2017-05-06 13:34:16,492 [Thread-11:86080] [django.request:152] [base:get_response] [WARNING]- Not Found: /admin/lib/jquery.validation/1.14.0/messages_zh.js
2017-05-06 13:34:16,493 [Thread-12:86068] [django.request:152] [base:get_response] [WARNING]- Not Found: /admin/lib/jquery.validation/1.14.0/jquery.validate.js
2017-05-06 13:34:16,545 [Thread-13:86024] [django.request:152] [base:get_response] [WARNING]- Not Found: /admin/lib/jquery.validation/1.14.0/validate-methods.js
2017-05-06 13:34:16,611 [Thread-14:86032] [django.request:152] [base:get_response] [WARNING]- Not Found: /admin/lib/jquery.validation/1.14.0/messages_zh.js
2017-05-06 13:38:24,691 [Thread-10:84392] [django.request:152] [base:get_response] [WARNING]- Not Found: /admin/lib/My97DatePicker/4.8/WdatePicker.js
2017-05-06 13:38:24,690 [Thread-12:86644] [django.request:152] [base:get_response] [WARNING]- Not Found: /admin/lib/jquery.validation/1.14.0/validate-methods.js
2017-05-06 13:38:24,697 [Thread-11:86836] [django.request:152] [base:get_response] [WARNING]- Not Found: /admin/lib/jquery.validation/1.14.0/jquery.validate.js
2017-05-06 13:38:24,706 [Thread-13:86640] [django.request:152] [base:get_response] [WARNING]- Not Found: /admin/lib/jquery.validation/1.14.0/messages_zh.js
2017-05-06 13:38:57,997 [Thread-17:85744] [django.request:152] [base:get_response] [WARNING]- Not Found: /admin/lib/My97DatePicker/4.8/WdatePicker.js
2017-05-06 13:38:58,006 [Thread-18:86272] [django.request:152] [base:get_response] [WARNING]- Not Found: /admin/lib/jquery.validation/1.14.0/jquery.validate.js
2017-05-06 13:38:58,006 [Thread-19:86252] [django.request:152] [base:get_response] [WARNING]- Not Found: /admin/lib/jquery.validation/1.14.0/messages_zh.js
2017-05-06 13:38:58,019 [Thread-20:85976] [django.request:152] [base:get_response] [WARNING]- Not Found: /admin/lib/jquery.validation/1.14.0/validate-methods.js
2017-05-06 13:38:58,051 [Thread-21:84012] [django.request:152] [base:get_response] [WARNING]- Not Found: /admin/lib/jquery.validation/1.14.0/messages_zh.js
2017-05-06 13:40:07,048 [Thread-45:86852] [django.request:152] [base:get_response] [WARNING]- Not Found: /admin/lib/jquery.validation/1.14.0/jquery.validate.js
2017-05-06 13:40:07,098 [Thread-46:86408] [django.request:152] [base:get_response] [WARNING]- Not Found: /admin/lib/My97DatePicker/4.8/WdatePicker.js
2017-05-06 13:40:07,108 [Thread-47:86556] [django.request:152] [base:get_response] [WARNING]- Not Found: /admin/lib/jquery.validation/1.14.0/validate-methods.js
2017-05-06 13:40:07,111 [Thread-48:84024] [django.request:152] [base:get_response] [WARNING]- Not Found: /admin/lib/jquery.validation/1.14.0/messages_zh.js
2017-05-06 13:40:07,161 [Thread-49:85028] [django.request:152] [base:get_response] [WARNING]- Not Found: /admin/lib/jquery.validation/1.14.0/jquery.validate.js
2017-05-06 13:40:07,194 [Thread-50:83164] [django.request:152] [base:get_response] [WARNING]- Not Found: /admin/lib/jquery.validation/1.14.0/validate-methods.js
2017-05-06 13:40:07,220 [Thread-51:85084] [django.request:152] [base:get_response] [WARNING]- Not Found: /admin/lib/jquery.validation/1.14.0/messages_zh.js
2017-05-06 13:40:35,831 [Thread-55:86732] [django.request:152] [base:get_response] [WARNING]- Not Found: /admin/lib/jquery.validation/1.14.0/jquery.validate.js
2017-05-06 13:40:35,835 [Thread-57:86928] [django.request:152] [base:get_response] [WARNING]- Not Found: /admin/lib/My97DatePicker/4.8/WdatePicker.js
2017-05-06 13:40:35,836 [Thread-56:85984] [django.request:152] [base:get_response] [WARNING]- Not Found: /admin/lib/jquery.validation/1.14.0/validate-methods.js
2017-05-06 13:40:35,846 [Thread-58:86236] [django.request:152] [base:get_response] [WARNING]- Not Found: /admin/lib/jquery.validation/1.14.0/messages_zh.js
2017-05-06 13:40:35,877 [Thread-59:86100] [django.request:152] [base:get_response] [WARNING]- Not Found: /admin/lib/jquery.validation/1.14.0/jquery.validate.js
2017-05-06 13:40:35,898 [Thread-60:86572] [django.request:152] [base:get_response] [WARNING]- Not Found: /admin/lib/jquery.validation/1.14.0/validate-methods.js
2017-05-06 13:40:35,927 [Thread-61:82200] [django.request:152] [base:get_response] [WARNING]- Not Found: /admin/lib/jquery.validation/1.14.0/messages_zh.js
2017-05-06 13:41:09,828 [Thread-65:79888] [django.request:152] [base:get_response] [WARNING]- Not Found: /admin/lib/My97DatePicker/4.8/WdatePicker.js
2017-05-06 13:41:09,831 [Thread-66:86820] [django.request:152] [base:get_response] [WARNING]- Not Found: /admin/lib/jquery.validation/1.14.0/jquery.validate.js
2017-05-06 13:41:09,832 [Thread-68:82172] [django.request:152] [base:get_response] [WARNING]- Not Found: /admin/lib/jquery.validation/1.14.0/validate-methods.js
2017-05-06 13:41:09,834 [Thread-67:85112] [django.request:152] [base:get_response] [WARNING]- Not Found: /admin/lib/jquery.validation/1.14.0/messages_zh.js
2017-05-06 13:41:09,871 [Thread-69:85920] [django.request:152] [base:get_response] [WARNING]- Not Found: /admin/lib/jquery.validation/1.14.0/messages_zh.js
2017-05-08 16:21:13,831 [Thread-7:7864] [django.request:152] [base:get_response] [WARNING]- Not Found: /
2017-05-08 16:21:13,957 [Thread-8:7604] [django.request:152] [base:get_response] [WARNING]- Not Found: /favicon.ico
2017-05-08 16:21:20,749 [Thread-9:7180] [django.request:152] [base:get_response] [WARNING]- Not Found: /user/reg.action
2017-05-08 16:37:31,177 [Thread-30:7676] [django.request:152] [base:get_response] [WARNING]- Not Found: /admin/lib/jquery.validation/1.14.0/validate-methods.js
2017-05-08 16:37:31,177 [Thread-29:5744] [django.request:152] [base:get_response] [WARNING]- Not Found: /admin/lib/My97DatePicker/4.8/WdatePicker.js
2017-05-08 16:37:31,180 [Thread-31:7648] [django.request:152] [base:get_response] [WARNING]- Not Found: /admin/lib/jquery.validation/1.14.0/jquery.validate.js
2017-05-08 16:37:31,181 [Thread-32:6972] [django.request:152] [base:get_response] [WARNING]- Not Found: /admin/lib/jquery.validation/1.14.0/messages_zh.js
2017-05-08 16:37:43,625 [Thread-35:7180] [django.request:152] [base:get_response] [WARNING]- Not Found: /admin/lib/My97DatePicker/4.8/WdatePicker.js
2017-05-08 16:37:43,632 [Thread-36:4336] [django.request:152] [base:get_response] [WARNING]- Not Found: /admin/lib/jquery.validation/1.14.0/validate-methods.js
2017-05-08 16:37:43,634 [Thread-37:1668] [django.request:152] [base:get_response] [WARNING]- Not Found: /admin/lib/jquery.validation/1.14.0/jquery.validate.js
2017-05-08 16:37:43,638 [Thread-38:7856] [django.request:152] [base:get_response] [WARNING]- Not Found: /admin/lib/jquery.validation/1.14.0/messages_zh.js
2017-05-08 16:37:43,661 [Thread-39:3548] [django.request:152] [base:get_response] [WARNING]- Not Found: /admin/lib/jquery.validation/1.14.0/validate-methods.js
2017-05-08 16:37:43,690 [Thread-40:7876] [django.request:152] [base:get_response] [WARNING]- Not Found: /admin/lib/jquery.validation/1.14.0/messages_zh.js
2017-05-08 16:38:12,726 [Thread-45:1828] [django.request:152] [base:get_response] [WARNING]- Not Found: /admin/lib/My97DatePicker/4.8/WdatePicker.js
2017-05-08 16:38:12,726 [Thread-46:6280] [django.request:152] [base:get_response] [WARNING]- Not Found: /admin/lib/jquery.validation/1.14.0/jquery.validate.js
2017-05-08 16:38:12,729 [Thread-47:4588] [django.request:152] [base:get_response] [WARNING]- Not Found: /admin/lib/jquery.validation/1.14.0/validate-methods.js
2017-05-08 16:38:12,730 [Thread-48:7472] [django.request:152] [base:get_response] [WARNING]- Not Found: /admin/lib/jquery.validation/1.14.0/messages_zh.js
2017-05-08 16:38:12,789 [Thread-49:6200] [django.request:152] [base:get_response] [WARNING]- Not Found: /admin/lib/jquery.validation/1.14.0/messages_zh.js
2017-05-10 09:59:51,683 [Thread-7:24200] [django.request:124] [exception:handle_uncaught_exception] [ERROR]- Internal Server Error: /admin/project_action_to_test_env
Traceback (most recent call last):
  File "D:\python\2.7\setuppath\lib\site-packages\django\core\handlers\exception.py", line 39, in inner
    response = get_response(request)
  File "D:\python\2.7\setuppath\lib\site-packages\django\core\handlers\base.py", line 187, in _get_response
    response = self.process_exception_by_middleware(e, request)
  File "D:\python\2.7\setuppath\lib\site-packages\django\core\handlers\base.py", line 185, in _get_response
    response = wrapped_callback(request, *callback_args, **callback_kwargs)
  File "E:/my/projects/python/git_web_hooks\apps\views_admin.py", line 127, in to_test_env_action
    deploy_result = deploy(project_info['develop_server_ip'], project_info['develop_server_dir'], project_info['develop_server_account'], project_info['test_server_ip'], project_info['test_server_dir'], project_info['test_server_account'])
TypeError: deploy() takes exactly 7 arguments (6 given)
2017-05-10 17:59:29,538 [Thread-7:7828] [django.request:152] [base:get_response] [WARNING]- Not Found: /
2017-05-10 17:59:29,667 [Thread-8:5828] [django.request:152] [base:get_response] [WARNING]- Not Found: /favicon.ico
2017-05-11 12:30:37,437 [Thread-23:13708] [django.request:152] [base:get_response] [WARNING]- Not Found: /admin/lib/My97DatePicker/4.8/WdatePicker.js
2017-05-11 12:30:37,582 [Thread-24:14232] [django.request:152] [base:get_response] [WARNING]- Not Found: /admin/lib/jquery.validation/1.14.0/jquery.validate.js
2017-05-11 12:30:37,585 [Thread-26:13228] [django.request:152] [base:get_response] [WARNING]- Not Found: /admin/lib/jquery.validation/1.14.0/messages_zh.js
2017-05-11 12:30:37,588 [Thread-25:13656] [django.request:152] [base:get_response] [WARNING]- Not Found: /admin/lib/jquery.validation/1.14.0/validate-methods.js
2017-05-11 12:30:37,654 [Thread-27:14060] [django.request:152] [base:get_response] [WARNING]- Not Found: /admin/lib/jquery.validation/1.14.0/validate-methods.js
2017-05-11 12:30:37,697 [Thread-28:14224] [django.request:152] [base:get_response] [WARNING]- Not Found: /admin/lib/jquery.validation/1.14.0/messages_zh.js
2017-05-11 12:31:45,770 [Thread-33:13956] [django.request:152] [base:get_response] [WARNING]- Not Found: /admin/lib/jquery.validation/1.14.0/validate-methods.js
2017-05-11 12:31:45,799 [Thread-34:13720] [django.request:152] [base:get_response] [WARNING]- Not Found: /admin/lib/jquery.validation/1.14.0/jquery.validate.js
2017-05-11 12:31:45,802 [Thread-35:13504] [django.request:152] [base:get_response] [WARNING]- Not Found: /admin/lib/My97DatePicker/4.8/WdatePicker.js
2017-05-11 12:31:45,802 [Thread-36:13540] [django.request:152] [base:get_response] [WARNING]- Not Found: /admin/lib/jquery.validation/1.14.0/messages_zh.js
2017-05-11 12:31:45,904 [Thread-37:14148] [django.request:152] [base:get_response] [WARNING]- Not Found: /admin/lib/jquery.validation/1.14.0/validate-methods.js
2017-05-11 12:31:46,000 [Thread-38:14204] [django.request:152] [base:get_response] [WARNING]- Not Found: /admin/lib/jquery.validation/1.14.0/messages_zh.js
2017-05-11 12:31:51,937 [Thread-40:12420] [django.request:152] [base:get_response] [WARNING]- Not Found: /admin/lib/My97DatePicker/4.8/WdatePicker.js
2017-05-11 12:31:51,944 [Thread-41:12312] [django.request:152] [base:get_response] [WARNING]- Not Found: /admin/lib/jquery.validation/1.14.0/jquery.validate.js
2017-05-11 12:31:51,948 [Thread-42:13568] [django.request:152] [base:get_response] [WARNING]- Not Found: /admin/lib/jquery.validation/1.14.0/validate-methods.js
2017-05-11 12:31:51,950 [Thread-43:12864] [django.request:152] [base:get_response] [WARNING]- Not Found: /admin/lib/jquery.validation/1.14.0/messages_zh.js
2017-05-11 12:31:52,010 [Thread-44:13916] [django.request:152] [base:get_response] [WARNING]- Not Found: /admin/lib/jquery.validation/1.14.0/messages_zh.js
2017-05-11 12:32:22,786 [Thread-46:13728] [django.request:152] [base:get_response] [WARNING]- Not Found: /admin/lib/My97DatePicker/4.8/WdatePicker.js
2017-05-11 12:32:22,795 [Thread-47:11632] [django.request:152] [base:get_response] [WARNING]- Not Found: /admin/lib/jquery.validation/1.14.0/messages_zh.js
2017-05-11 12:32:22,796 [Thread-48:12248] [django.request:152] [base:get_response] [WARNING]- Not Found: /admin/lib/jquery.validation/1.14.0/validate-methods.js
2017-05-11 12:32:22,799 [Thread-49:10560] [django.request:152] [base:get_response] [WARNING]- Not Found: /admin/lib/jquery.validation/1.14.0/jquery.validate.js
2017-05-11 12:32:22,859 [Thread-50:13508] [django.request:152] [base:get_response] [WARNING]- Not Found: /admin/lib/jquery.validation/1.14.0/validate-methods.js
2017-05-11 12:32:22,904 [Thread-51:12184] [django.request:152] [base:get_response] [WARNING]- Not Found: /admin/lib/jquery.validation/1.14.0/messages_zh.js
2017-05-11 12:35:56,068 [Thread-92:12260] [django.request:152] [base:get_response] [WARNING]- Not Found: /admin/lib/My97DatePicker/4.8/WdatePicker.js
2017-05-11 12:35:56,078 [Thread-93:13320] [django.request:152] [base:get_response] [WARNING]- Not Found: /admin/lib/jquery.validation/1.14.0/jquery.validate.js
2017-05-11 12:35:56,085 [Thread-94:13396] [django.request:152] [base:get_response] [WARNING]- Not Found: /admin/lib/jquery.validation/1.14.0/validate-methods.js
2017-05-11 12:35:56,085 [Thread-95:14000] [django.request:152] [base:get_response] [WARNING]- Not Found: /admin/lib/jquery.validation/1.14.0/messages_zh.js
2017-05-11 12:35:56,141 [Thread-96:13392] [django.request:152] [base:get_response] [WARNING]- Not Found: /admin/lib/jquery.validation/1.14.0/messages_zh.js
2017-05-11 12:36:08,461 [Thread-118:3552] [django.request:152] [base:get_response] [WARNING]- Not Found: /admin/lib/My97DatePicker/4.8/WdatePicker.js
2017-05-11 12:36:08,464 [Thread-119:8032] [django.request:152] [base:get_response] [WARNING]- Not Found: /admin/lib/jquery.validation/1.14.0/jquery.validate.js
2017-05-11 12:36:08,471 [Thread-120:14200] [django.request:152] [base:get_response] [WARNING]- Not Found: /admin/lib/jquery.validation/1.14.0/messages_zh.js
2017-05-11 12:36:08,474 [Thread-121:14220] [django.request:152] [base:get_response] [WARNING]- Not Found: /admin/lib/jquery.validation/1.14.0/validate-methods.js
2017-05-11 12:36:08,555 [Thread-122:14156] [django.request:152] [base:get_response] [WARNING]- Not Found: /admin/lib/jquery.validation/1.14.0/jquery.validate.js
2017-05-11 12:36:08,615 [Thread-123:12984] [django.request:152] [base:get_response] [WARNING]- Not Found: /admin/lib/jquery.validation/1.14.0/validate-methods.js
2017-05-11 12:36:08,661 [Thread-124:12596] [django.request:152] [base:get_response] [WARNING]- Not Found: /admin/lib/jquery.validation/1.14.0/messages_zh.js
2017-05-11 12:36:26,142 [Thread-146:9488] [django.request:152] [base:get_response] [WARNING]- Not Found: /admin/lib/My97DatePicker/4.8/WdatePicker.js
2017-05-11 12:36:26,151 [Thread-147:12380] [django.request:152] [base:get_response] [WARNING]- Not Found: /admin/lib/jquery.validation/1.14.0/validate-methods.js
2017-05-11 12:36:26,155 [Thread-149:13748] [django.request:152] [base:get_response] [WARNING]- Not Found: /admin/lib/jquery.validation/1.14.0/messages_zh.js
2017-05-11 12:36:26,164 [Thread-148:11488] [django.request:152] [base:get_response] [WARNING]- Not Found: /admin/lib/jquery.validation/1.14.0/jquery.validate.js
2017-05-11 12:36:26,239 [Thread-150:14032] [django.request:152] [base:get_response] [WARNING]- Not Found: /admin/lib/jquery.validation/1.14.0/validate-methods.js
2017-05-11 12:36:26,293 [Thread-151:13104] [django.request:152] [base:get_response] [WARNING]- Not Found: /admin/lib/jquery.validation/1.14.0/messages_zh.js
2017-05-11 12:36:32,217 [Thread-154:14140] [django.request:152] [base:get_response] [WARNING]- Not Found: /admin/lib/My97DatePicker/4.8/WdatePicker.js
2017-05-11 12:36:32,219 [Thread-153:14320] [django.request:152] [base:get_response] [WARNING]- Not Found: /admin/lib/jquery.validation/1.14.0/jquery.validate.js
2017-05-11 12:36:32,249 [Thread-156:13776] [django.request:152] [base:get_response] [WARNING]- Not Found: /admin/lib/jquery.validation/1.14.0/messages_zh.js
2017-05-11 12:36:32,250 [Thread-155:10748] [django.request:152] [base:get_response] [WARNING]- Not Found: /admin/lib/jquery.validation/1.14.0/validate-methods.js
2017-05-11 12:36:32,298 [Thread-157:13972] [django.request:152] [base:get_response] [WARNING]- Not Found: /admin/lib/jquery.validation/1.14.0/messages_zh.js
2017-05-11 12:42:10,275 [Thread-166:13336] [django.request:152] [base:get_response] [WARNING]- Not Found: /admin/lib/My97DatePicker/4.8/WdatePicker.js
2017-05-11 12:42:10,335 [Thread-167:13320] [django.request:152] [base:get_response] [WARNING]- Not Found: /admin/lib/jquery.validation/1.14.0/validate-methods.js
2017-05-11 12:42:10,335 [Thread-168:13792] [django.request:152] [base:get_response] [WARNING]- Not Found: /admin/lib/jquery.validation/1.14.0/jquery.validate.js
2017-05-11 12:42:10,336 [Thread-169:12824] [django.request:152] [base:get_response] [WARNING]- Not Found: /admin/lib/jquery.validation/1.14.0/messages_zh.js
2017-05-11 13:11:08,852 [Thread-150:11556] [django.request:124] [exception:handle_uncaught_exception] [ERROR]- Internal Server Error: /admin/project.to_produce_env
Traceback (most recent call last):
  File "D:\python\2.7\setuppath\lib\site-packages\django\core\handlers\exception.py", line 39, in inner
    response = get_response(request)
  File "D:\python\2.7\setuppath\lib\site-packages\django\core\handlers\base.py", line 187, in _get_response
    response = self.process_exception_by_middleware(e, request)
  File "D:\python\2.7\setuppath\lib\site-packages\django\core\handlers\base.py", line 185, in _get_response
    response = wrapped_callback(request, *callback_args, **callback_kwargs)
  File "E:/my/projects/python/git_web_hooks\apps\views_admin.py", line 145, in to_produce_env
    return render(request, 'to_produce_env.html', {'id': project_id, 'lists': list, 'record_count': len(list)})
  File "D:\python\2.7\setuppath\lib\site-packages\django\shortcuts.py", line 30, in render
    content = loader.render_to_string(template_name, context, request, using=using)
  File "D:\python\2.7\setuppath\lib\site-packages\django\template\loader.py", line 67, in render_to_string
    template = get_template(template_name, using=using)
  File "D:\python\2.7\setuppath\lib\site-packages\django\template\loader.py", line 21, in get_template
    return engine.get_template(template_name)
  File "D:\python\2.7\setuppath\lib\site-packages\django\template\backends\django.py", line 39, in get_template
    return Template(self.engine.get_template(template_name), self)
  File "D:\python\2.7\setuppath\lib\site-packages\django\template\engine.py", line 160, in get_template
    template, origin = self.find_template(template_name)
  File "D:\python\2.7\setuppath\lib\site-packages\django\template\engine.py", line 134, in find_template
    name, template_dirs=dirs, skip=skip,
  File "D:\python\2.7\setuppath\lib\site-packages\django\template\loaders\base.py", line 44, in get_template
    contents, origin, origin.template_name, self.engine,
  File "D:\python\2.7\setuppath\lib\site-packages\django\template\base.py", line 191, in __init__
    self.nodelist = self.compile_nodelist()
  File "D:\python\2.7\setuppath\lib\site-packages\django\template\base.py", line 233, in compile_nodelist
    return parser.parse()
  File "D:\python\2.7\setuppath\lib\site-packages\django\template\base.py", line 518, in parse
    raise self.error(token, e)
TemplateSyntaxError: Could not parse the remainder: ':"Y年m月d日 H时i分' from 'item.inserttime|date:"Y年m月d日 H时i分'
2017-05-11 13:26:18,476 [Thread-7:8712] [django.request:124] [exception:handle_uncaught_exception] [ERROR]- Internal Server Error: /admin/project.to_produce_env
Traceback (most recent call last):
  File "D:\python\2.7\setuppath\lib\site-packages\django\core\handlers\exception.py", line 39, in inner
    response = get_response(request)
  File "D:\python\2.7\setuppath\lib\site-packages\django\core\handlers\base.py", line 187, in _get_response
    response = self.process_exception_by_middleware(e, request)
  File "D:\python\2.7\setuppath\lib\site-packages\django\core\handlers\base.py", line 185, in _get_response
    response = wrapped_callback(request, *callback_args, **callback_kwargs)
  File "E:/my/projects/python/git_web_hooks\apps\views_admin.py", line 146, in to_produce_env
    item.inserttime = item.inserttime.strftime("%Y_%m_%d_%H_%M_%S")
AttributeError: 'dict' object has no attribute 'inserttime'
2017-05-11 13:26:48,230 [Thread-7:13884] [django.request:124] [exception:handle_uncaught_exception] [ERROR]- Internal Server Error: /admin/project.to_produce_env
Traceback (most recent call last):
  File "D:\python\2.7\setuppath\lib\site-packages\django\core\handlers\exception.py", line 39, in inner
    response = get_response(request)
  File "D:\python\2.7\setuppath\lib\site-packages\django\core\handlers\base.py", line 187, in _get_response
    response = self.process_exception_by_middleware(e, request)
  File "D:\python\2.7\setuppath\lib\site-packages\django\core\handlers\base.py", line 185, in _get_response
    response = wrapped_callback(request, *callback_args, **callback_kwargs)
  File "E:/my/projects/python/git_web_hooks\apps\views_admin.py", line 146, in to_produce_env
    item['inserttime'] = item['inserttime'].strftime("%Y_%m_%d_%H_%M_%S")
AttributeError: 'long' object has no attribute 'strftime'
2017-05-11 13:27:10,119 [Thread-7:11584] [django.request:124] [exception:handle_uncaught_exception] [ERROR]- Internal Server Error: /admin/project.to_produce_env
Traceback (most recent call last):
  File "D:\python\2.7\setuppath\lib\site-packages\django\core\handlers\exception.py", line 39, in inner
    response = get_response(request)
  File "D:\python\2.7\setuppath\lib\site-packages\django\core\handlers\base.py", line 187, in _get_response
    response = self.process_exception_by_middleware(e, request)
  File "D:\python\2.7\setuppath\lib\site-packages\django\core\handlers\base.py", line 185, in _get_response
    response = wrapped_callback(request, *callback_args, **callback_kwargs)
  File "E:/my/projects/python/git_web_hooks\apps\views_admin.py", line 146, in to_produce_env
    item['inserttime'] = int(item['inserttime']).strftime("%Y_%m_%d_%H_%M_%S")
AttributeError: 'int' object has no attribute 'strftime'
2017-05-11 13:28:47,586 [Thread-7:15332] [django.request:124] [exception:handle_uncaught_exception] [ERROR]- Internal Server Error: /admin/project.to_produce_env
Traceback (most recent call last):
  File "D:\python\2.7\setuppath\lib\site-packages\django\core\handlers\exception.py", line 39, in inner
    response = get_response(request)
  File "D:\python\2.7\setuppath\lib\site-packages\django\core\handlers\base.py", line 187, in _get_response
    response = self.process_exception_by_middleware(e, request)
  File "D:\python\2.7\setuppath\lib\site-packages\django\core\handlers\base.py", line 185, in _get_response
    response = wrapped_callback(request, *callback_args, **callback_kwargs)
  File "E:/my/projects/python/git_web_hooks\apps\views_admin.py", line 147, in to_produce_env
    item['inserttime'] = temp_time.strftime("%Y_%m_%d_%H_%M_%S")
AttributeError: 'time.struct_time' object has no attribute 'strftime'
2017-05-11 13:29:35,927 [Thread-7:14996] [django.request:124] [exception:handle_uncaught_exception] [ERROR]- Internal Server Error: /admin/project.to_produce_env
Traceback (most recent call last):
  File "D:\python\2.7\setuppath\lib\site-packages\django\core\handlers\exception.py", line 39, in inner
    response = get_response(request)
  File "D:\python\2.7\setuppath\lib\site-packages\django\core\handlers\base.py", line 187, in _get_response
    response = self.process_exception_by_middleware(e, request)
  File "D:\python\2.7\setuppath\lib\site-packages\django\core\handlers\base.py", line 185, in _get_response
    response = wrapped_callback(request, *callback_args, **callback_kwargs)
  File "E:/my/projects/python/git_web_hooks\apps\views_admin.py", line 149, in to_produce_env
    return render(request, 'to_produce_env.html', {'id': project_id, 'lists': lists, 'record_count': len(list)})
TypeError: object of type 'type' has no len()
2017-05-11 14:41:43,490 [Thread-8:13948] [django.request:152] [base:get_response] [WARNING]- Not Found: /admin/lib/My97DatePicker/4.8/WdatePicker.js
2017-05-11 14:41:43,494 [Thread-9:14320] [django.request:152] [base:get_response] [WARNING]- Not Found: /admin/lib/jquery.validation/1.14.0/jquery.validate.js
2017-05-11 14:41:43,497 [Thread-10:14624] [django.request:152] [base:get_response] [WARNING]- Not Found: /admin/lib/jquery.validation/1.14.0/validate-methods.js
2017-05-11 14:41:43,500 [Thread-11:12972] [django.request:152] [base:get_response] [WARNING]- Not Found: /admin/lib/jquery.validation/1.14.0/messages_zh.js
2017-05-11 14:41:43,542 [Thread-12:16148] [django.request:152] [base:get_response] [WARNING]- Not Found: /admin/lib/jquery.validation/1.14.0/messages_zh.js
2017-05-11 14:42:21,351 [Thread-16:11784] [django.request:152] [base:get_response] [WARNING]- Not Found: /admin/lib/My97DatePicker/4.8/WdatePicker.js
2017-05-11 14:42:21,362 [Thread-17:15832] [django.request:152] [base:get_response] [WARNING]- Not Found: /admin/lib/jquery.validation/1.14.0/validate-methods.js
2017-05-11 14:42:21,365 [Thread-18:1716] [django.request:152] [base:get_response] [WARNING]- Not Found: /admin/lib/jquery.validation/1.14.0/jquery.validate.js
2017-05-11 14:42:21,365 [Thread-19:14676] [django.request:152] [base:get_response] [WARNING]- Not Found: /admin/lib/jquery.validation/1.14.0/messages_zh.js
2017-05-11 14:42:21,401 [Thread-20:15632] [django.request:152] [base:get_response] [WARNING]- Not Found: /admin/lib/jquery.validation/1.14.0/validate-methods.js
2017-05-11 14:42:21,430 [Thread-21:15736] [django.request:152] [base:get_response] [WARNING]- Not Found: /admin/lib/jquery.validation/1.14.0/messages_zh.js
2017-05-11 17:12:20,789 [Thread-9:2408] [django.request:152] [base:get_response] [WARNING]- Not Found: /admin/lib/My97DatePicker/4.8/WdatePicker.js
2017-05-11 17:12:20,796 [Thread-10:17188] [django.request:152] [base:get_response] [WARNING]- Not Found: /admin/lib/jquery.validation/1.14.0/jquery.validate.js
2017-05-11 17:12:20,803 [Thread-11:18308] [django.request:152] [base:get_response] [WARNING]- Not Found: /admin/lib/jquery.validation/1.14.0/validate-methods.js
2017-05-11 17:12:20,805 [Thread-12:19396] [django.request:152] [base:get_response] [WARNING]- Not Found: /admin/lib/jquery.validation/1.14.0/messages_zh.js
2017-05-11 17:12:20,872 [Thread-13:18924] [django.request:152] [base:get_response] [WARNING]- Not Found: /admin/lib/jquery.validation/1.14.0/messages_zh.js
2017-05-11 17:13:10,105 [Thread-16:1800] [django.request:152] [base:get_response] [WARNING]- Not Found: /admin/lib/My97DatePicker/4.8/WdatePicker.js
2017-05-11 17:13:10,109 [Thread-17:18060] [django.request:152] [base:get_response] [WARNING]- Not Found: /admin/lib/jquery.validation/1.14.0/jquery.validate.js
2017-05-11 17:13:10,114 [Thread-18:19392] [django.request:152] [base:get_response] [WARNING]- Not Found: /admin/lib/jquery.validation/1.14.0/validate-methods.js
2017-05-11 17:13:10,115 [Thread-19:17168] [django.request:152] [base:get_response] [WARNING]- Not Found: /admin/lib/jquery.validation/1.14.0/messages_zh.js
2017-05-11 17:13:19,676 [Thread-42:19060] [django.request:152] [base:get_response] [WARNING]- Not Found: /admin/lib/My97DatePicker/4.8/WdatePicker.js
2017-05-11 17:13:19,736 [Thread-43:18404] [django.request:152] [base:get_response] [WARNING]- Not Found: /admin/lib/jquery.validation/1.14.0/messages_zh.js
2017-05-11 17:13:19,743 [Thread-44:19328] [django.request:152] [base:get_response] [WARNING]- Not Found: /admin/lib/jquery.validation/1.14.0/validate-methods.js
2017-05-11 17:13:19,746 [Thread-45:17776] [django.request:152] [base:get_response] [WARNING]- Not Found: /admin/lib/jquery.validation/1.14.0/jquery.validate.js
2017-05-11 17:13:19,809 [Thread-46:19360] [django.request:152] [base:get_response] [WARNING]- Not Found: /admin/lib/jquery.validation/1.14.0/validate-methods.js
2017-05-11 17:13:19,858 [Thread-47:18208] [django.request:152] [base:get_response] [WARNING]- Not Found: /admin/lib/jquery.validation/1.14.0/messages_zh.js
2017-05-12 15:59:29,569 [Thread-7:28528] [django.request:152] [base:get_response] [WARNING]- Not Found: /
2017-05-25 11:45:02,582 [Thread-7:103728] [django.request:124] [exception:handle_uncaught_exception] [ERROR]- Internal Server Error: /web_hook/push
Traceback (most recent call last):
  File "D:\python\2.7\setuppath\lib\site-packages\django\core\handlers\exception.py", line 39, in inner
    response = get_response(request)
  File "D:\python\2.7\setuppath\lib\site-packages\django\core\handlers\base.py", line 187, in _get_response
    response = self.process_exception_by_middleware(e, request)
  File "D:\python\2.7\setuppath\lib\site-packages\django\core\handlers\base.py", line 185, in _get_response
    response = wrapped_callback(request, *callback_args, **callback_kwargs)
  File "E:/my/projects/python/git_web_hooks\apps\views.py", line 82, in push
    post_content = json.loads(body_unicode)
  File "D:\python\2.7\setuppath\lib\json\__init__.py", line 339, in loads
    return _default_decoder.decode(s)
  File "D:\python\2.7\setuppath\lib\json\decoder.py", line 364, in decode
    obj, end = self.raw_decode(s, idx=_w(s, 0).end())
  File "D:\python\2.7\setuppath\lib\json\decoder.py", line 382, in raw_decode
    raise ValueError("No JSON object could be decoded")
ValueError: No JSON object could be decoded
